Workbook

Sheet Participant_Data
A1: record_id | B1: assessment_id | C1: assessment_date | D1: Role | E1: age | F1: age_group01 | G1: sex | H1: Education | I1: Marital_status | J1: Income | K1: Income_oldage | L1: Income_Pension | M1: Income_spouse | N1: Income_children | O1: Income_work | P1: DM | Q1: HT | R1: DLP | S1: CKD | T1: CA | U1: Other | V1: Other_text | W1: Living_with | X1: scr_bw | Y1: scr_app | Z1: scr_act | AA1: scr_dx | AB1: ass_meal | AC1: ass_intake | AD1: ass_type | AE1: ass_rice_starch | AF1: ass_meat_egg | AG1: ass_milk | AH1: ass_fruit | AI1: ass_veget | AJ1: ass_water | AK1: ass_sweetdrink | AL1: ass_cook | AM1: ass_oil | AN1: D1_total | AO1: D2_total | AP1: D3_total | AQ1: wc_input | AR1: wc_unit | AS1: wc_cm
A2: 1 | D2: 1 | E2: 63 | F2: =IF(E2="","",IF(E2<70,0,1)) -> 0 | G2: 1 | H2: 3 | I2: 2 | J2: 3 | K2: 0 | L2: 1 | M2: 0 | N2: 0 | O2: 0 | P2: 0 | Q2: 1 | R2: 1 | S2: 0 | T2: 0 | U2: 1 | V2: Gout | W2: 2 | X2: 2 | Y2: 2 | Z2: 2 | AA2: 4 | AB2: 2 | AC2: 2 | AD2: 2 | AE2: 2 | AF2: 0 | AG2: 2 | AH2: 0 | AI2: 2 | AJ2: 2 | AK2: 2 | AL2: 2 | AM2: 0 | AN2: =IF(COUNTA(AB2:AD2)=0,"",SUM(AB2:AD2)) -> 6 | AO2: 8 | AP2: 4 | AQ2: 97 | AR2: cm | AS2: =IF(AQ2="","",IF(AR2="cm",AQ2,IF(AR2="inch",AQ2*2.54,""))) -> 97
A3: 2 | D3: 1 | E3: 69 | F3: =IF(E3="","",IF(E3<70,0,1)) -> 0 | G3: 2 | H3: 1 | I3: 2 | J3: 1 | K3: 1 | L3: 0 | M3: 0 | N3: 0 | O3: 0 | P3: 0 | Q3: 0 | R3: 0 | S3: 0 | T3: 0 | U3: 1 | V3: ภูมิแพ้ หืดหอบ | W3: 2 | X3: 2 | Y3: 2 | Z3: 0 | AA3: 2 | AB3: 2 | AC3: 2 | AD3: 2 | AE3: 0 | AF3: 2 | AG3: 2 | AH3: 4 | AI3: 2 | AJ3: 2 | AK3: 2 | AL3: 2 | AM3: 0 | AN3: =IF(COUNTA(AB3:AD3)=0,"",SUM(AB3:AD3)) -> 6 | AO3: 12 | AP3: 4 | AQ3: 72 | AR3: cm | AS3: =IF(AQ3="","",IF(AR3="cm",AQ3,IF(AR3="inch",AQ3*2.54,""))) -> 72
A4: 3 | D4: 1 | E4: 66 | F4: =IF(E4="","",IF(E4<70,0,1)) -> 0 | G4: 2 | H4: 2 | I4: 2 | J4: 1 | K4: 1 | L4: 0 | M4: 0 | N4: 0 | O4: 0 | P4: 0 | Q4: 0 | R4: 0 | S4: 0 | T4: 0 | U4: 1 | V4: ภูมิแพ้ | W4: 2 | X4: 2 | Y4: 2 | Z4: 2 | AA4: 2 | AB4: 2 | AC4: 0 | AD4: 2 | AE4: 0 | AF4: 0 | AG4: 2 | AH4: 0 | AI4: 2 | AJ4: 0 | AK4: 2 | AL4: 2 | AM4: 2 | AN4: =IF(COUNTA(AB4:AD4)=0,"",SUM(AB4:AD4)) -> 4 | AO4: 4 | AP4: 6 | AQ4: 68 | AR4: cm | AS4: =IF(AQ4="","",IF(AR4="cm",AQ4,IF(AR4="inch",AQ4*2.54,""))) -> 68
A5: 4 | D5: 1 | E5: 68 | F5: =IF(E5="","",IF(E5<70,0,1)) -> 0 | G5: 2 | H5: 2 | I5: 1 | J5: 1 | K5: 1 | L5: 0 | M5: 0 | N5: 0 | O5: 0 | P5: 0 | Q5: 0 | R5: 1 | S5: 0 | T5: 0 | U5: 0 | V5: ไม่มีโรค | W5: 4 | X5: 2 | Y5: 2 | Z5: 2 | AA5: 4 | AB5: 2 | AC5: 2 | AD5: 2 | AE5: 0 | AF5: 0 | AG5: 2 | AH5: 0 | AI5: 0 | AJ5: 2 | AK5: 4 | AL5: 2 | AM5: 0 | AN5: =IF(COUNTA(AB5:AD5)=0,"",SUM(AB5:AD5)) -> 6 | AO5: 4 | AP5: 6 | AQ5: 59 | AR5: cm | AS5: =IF(AQ5="","",IF(AR5="cm",AQ5,IF(AR5="inch",AQ5*2.54,""))) -> 59
A6: 5 | D6: 1 | E6: 65 | F6: =IF(E6="","",IF(E6<70,0,1)) -> 0 | G6: 2 | H6: 3 | I6: 1 | J6: 1 | K6: 0 | L6: 1 | M6: 0 | N6: 0 | O6: 0 | P6: 0 | Q6: 1 | R6: 1 | S6: 0 | T6: 0 | U6: 0 | W6: 4 | X6: 2 | Y6: 2 | Z6: 2 | AA6: 4 | AB6: 2 | AC6: 2 | AD6: 2 | AE6: 0 | AF6: 0 | AG6: 2 | AH6: 2 | AI6: 2 | AJ6: 2 | AK6: 2 | AL6: 2 | AM6: 0 | AN6: =IF(COUNTA(AB6:AD6)=0,"",SUM(AB6:AD6)) -> 6 | AO6: 8 | AP6: 4 | AQ6: 88 | AR6: cm | AS6: =IF(AQ6="","",IF(AR6="cm",AQ6,IF(AR6="inch",AQ6*2.54,""))) -> 88
A7: 6 | D7: 1 | E7: 63 | F7: =IF(E7="","",IF(E7<70,0,1)) -> 0 | G7: 2 | H7: 2 | I7: 3 | J7: 1 | K7: 1 | L7: 0 | M7: 0 | N7: 0 | O7: 0 | P7: 0 | Q7: 0 | R7: 1 | S7: 0 | T7: 0 | U7: 0 | W7: 4 | X7: 4 | Y7: 2 | Z7: 2 | AA7: 4 | AB7: 2 | AC7: 2 | AD7: 2 | AE7: 0 | AF7: 0 | AG7: 2 | AH7: 0 | AI7: 0 | AJ7: 0 | AK7: 2 | AL7: 2 | AM7: 0 | AN7: =IF(COUNTA(AB7:AD7)=0,"",SUM(AB7:AD7)) -> 6 | AO7: 2 | AP7: 4 | AQ7: 77 | AR7: cm | AS7: =IF(AQ7="","",IF(AR7="cm",AQ7,IF(AR7="inch",AQ7*2.54,""))) -> 77
A8: 7 | D8: 1 | E8: 60 | F8: =IF(E8="","",IF(E8<70,0,1)) -> 0 | G8: 2 | H8: 2 | I8: 2 | J8: 1 | K8: 1 | L8: 0 | M8: 1 | N8: 0 | O8: 0 | P8: 1 | Q8: 1 | R8: 1 | S8: 0 | T8: 0 | U8: 0 | W8: 2 | X8: 4 | Y8: 2 | Z8: 2 | AA8: 4 | AB8: 2 | AC8: 0 | AD8: 2 | AE8: 0 | AF8: 2 | AG8: 2 | AH8: 0 | AI8: 0 | AJ8: 2 | AK8: 2 | AL8: 2 | AM8: 0 | AN8: =IF(COUNTA(AB8:AD8)=0,"",SUM(AB8:AD8)) -> 4 | AO8: 6 | AP8: 4 | AQ8: 94.5 | AR8: cm | AS8: =IF(AQ8="","",IF(AR8="cm",AQ8,IF(AR8="inch",AQ8*2.54,""))) -> 94.5
A9: 8 | D9: 1 | E9: 68 | F9: =IF(E9="","",IF(E9<70,0,1)) -> 0 | G9: 2 | H9: 2 | I9: 3 | J9: 1 | K9: 1 | L9: 0 | M9: 0 | N9: 0 | O9: 0 | P9: 0 | Q9: 1 | R9: 0 | S9: 0 | T9: 0 | U9: 0 | W9: 4 | X9: 2 | Y9: 2 | Z9: 0 | AA9: 4 | AB9: 2 | AC9: 0 | AD9: 2 | AE9: 0 | AF9: 0 | AG9: 2 | AH9: 0 | AI9: 0 | AJ9: 2 | AK9: 4 | AL9: 2 | AM9: 0 | AN9: =IF(COUNTA(AB9:AD9)=0,"",SUM(AB9:AD9)) -> 4 | AO9: 4 | AP9: 6 | AQ9: 95.5 | AR9: cm | AS9: =IF(AQ9="","",IF(AR9="cm",AQ9,IF(AR9="inch",AQ9*2.54,""))) -> 95.5
A10: 9 | D10: 1 | E10: 67 | F10: =IF(E10="","",IF(E10<70,0,1)) -> 0 | G10: 2 | H10: 2 | I10: 3 | J10: 1 | K10: 1 | L10: 0 | M10: 0 | N10: 0 | O10: 0 | P10: 0 | Q10: 0 | R10: 0 | S10: 0 | T10: 0 | U10: 0 | V10: ไม่มีโรค | W10: 4 | X10: 2 | Y10: 2 | Z10: 2 | AA10: 2 | AB10: 2 | AC10: 0 | AD10: 2 | AE10: 0 | AF10: 2 | AG10: 2 | AH10: 0 | AI10: 2 | AJ10: 2 | AK10: 2 | AL10: 2 | AM10: 0 | AN10: =IF(COUNTA(AB10:AD10)=0,"",SUM(AB10:AD10)) -> 4 | AO10: 8 | AP10: 4 | AQ10: 80 | AR10: cm | AS10: =IF(AQ10="","",IF(AR10="cm",AQ10,IF(AR10="inch",AQ10*2.54,""))) -> 80
A11: 10 | D11: 1 | E11: 61 | F11: =IF(E11="","",IF(E11<70,0,1)) -> 0 | G11: 2 | H11: 1 | I11: 3 | J11: 1 | K11: 1 | L11: 0 | M11: 0 | N11: 0 | O11: 0 | P11: 0 | Q11: 0 | R11: 0 | S11: 0 | T11: 0 | U11: 0 | V11: ไม่มีโรค | W11: 4 | X11: 4 | Y11: 2 | Z11: 2 | AA11: 2 | AB11: 2 | AC11: 0 | AD11: 2 | AE11: 0 | AF11: 0 | AG11: 0 | AH11: 2 | AI11: 0 | AJ11: 2 | AK11: 2 | AL11: 2 | AM11: 0 | AN11: =IF(COUNTA(AB11:AD11)=0,"",SUM(AB11:AD11)) -> 4 | AO11: 4 | AP11: 4 | AQ11: 79.5 | AR11: cm | AS11: =IF(AQ11="","",IF(AR11="cm",AQ11,IF(AR11="inch",AQ11*2.54,""))) -> 79.5
A12: 11 | D12: 1 | E12: 69 | F12: =IF(E12="","",IF(E12<70,0,1)) -> 0 | G12: 2 | H12: 2 | I12: 1 | J12: 1 | K12: 1 | L12: 0 | M12: 0 | N12: 1 | O12: 0 | P12: 0 | Q12: 0 | R12: 1 | S12: 0 | T12: 0 | U12: 0 | W12: 1 | X12: 2 | Y12: 0 | Z12: 2 | AA12: 4 | AB12: 2 | AC12: 0 | AD12: 2 | AE12: 0 | AF12: 0 | AG12: 2 | AH12: 2 | AI12: 2 | AJ12: 2 | AK12: 2 | AL12: 2 | AM12: 0 | AN12: =IF(COUNTA(AB12:AD12)=0,"",SUM(AB12:AD12)) -> 4 | AO12: 8 | AP12: 4 | AQ12: 84 | AR12: cm | AS12: =IF(AQ12="","",IF(AR12="cm",AQ12,IF(AR12="inch",AQ12*2.54,""))) -> 84
A13: 12 | D13: 1 | E13: 68 | F13: =IF(E13="","",IF(E13<70,0,1)) -> 0 | G13: 2 | H13: 2 | I13: 2 | J13: 1 | K13: 1 | L13: 0 | M13: 0 | N13: 1 | O13: 1 | P13: 0 | Q13: 1 | R13: 1 | S13: 0 | T13: 0 | U13: 0 | W13: 2 | X13: 4 | Y13: 4 | Z13: 2 | AA13: 4 | AB13: 2 | AC13: 2 | AD13: 2 | AE13: 0 | AF13: 2 | AG13: 2 | AH13: 2 | AI13: 2 | AJ13: 2 | AK13: 2 | AL13: 2 | AM13: 0 | AN13: =IF(COUNTA(AB13:AD13)=0,"",SUM(AB13:AD13)) -> 6 | AO13: 10 | AP13: 4 | AQ13: 83 | AR13: cm | AS13: =IF(AQ13="","",IF(AR13="cm",AQ13,IF(AR13="inch",AQ13*2.54,""))) -> 83
A14: 13 | D14: 1 | E14: 68 | F14: =IF(E14="","",IF(E14<70,0,1)) -> 0 | G14: 2 | H14: 3 | I14: 1 | J14: 1 | K14: 1 | L14: 0 | M14: 0 | N14: 0 | O14: 0 | P14: 0 | Q14: 0 | R14: 0 | S14: 0 | T14: 0 | U14: 0 | W14: 4 | X14: 2 | Y14: 2 | Z14: 2 | AA14: 2 | AB14: 2 | AC14: 2 | AD14: 2 | AE14: 0 | AF14: 0 | AG14: 0 | AH14: 0 | AI14: 0 | AJ14: 2 | AK14: 2 | AL14: 2 | AM14: 0 | AN14: =IF(COUNTA(AB14:AD14)=0,"",SUM(AB14:AD14)) -> 6 | AO14: 2 | AP14: 4 | AQ14: 64 | AR14: cm | AS14: =IF(AQ14="","",IF(AR14="cm",AQ14,IF(AR14="inch",AQ14*2.54,""))) -> 64
A15: 14 | D15: 1 | E15: 66 | F15: =IF(E15="","",IF(E15<70,0,1)) -> 0 | G15: 2 | H15: 3 | I15: 1 | J15: 1 | K15: 1 | L15: 0 | M15: 0 | N15: 0 | O15: 0 | P15: 0 | Q15: 1 | R15: 1 | S15: 0 | T15: 0 | U15: 0 | W15: 1 | X15: 2 | Y15: 0 | Z15: 0 | AA15: 4 | AB15: 2 | AC15: 2 | AD15: 2 | AE15: 0 | AF15: 0 | AG15: 0 | AH15: 0 | AI15: 0 | AJ15: 0 | AK15: 2 | AL15: 2 | AM15: 0 | AN15: =IF(COUNTA(AB15:AD15)=0,"",SUM(AB15:AD15)) -> 6 | AO15: 0 | AP15: 4 | AQ15: 59 | AR15: cm | AS15: =IF(AQ15="","",IF(AR15="cm",AQ15,IF(AR15="inch",AQ15*2.54,""))) -> 59
A16: 15 | D16: 1 | E16: 66 | F16: =IF(E16="","",IF(E16<70,0,1)) -> 0 | G16: 2 | H16: 3 | I16: 1 | J16: 1 | K16: 1 | L16: 0 | M16: 0 | N16: 0 | O16: 0 | P16: 0 | Q16: 0 | R16: 0 | S16: 0 | T16: 0 | U16: 1 | V16: โรคกระเพาะอาหาร กระดูกพรุน | W16: 4 | X16: 2 | Y16: 2 | Z16: 2 | AA16: 4 | AB16: 2 | AC16: 2 | AD16: 2 | AE16: 2 | AF16: 4 | AG16: 0 | AH16: 0 | AI16: 0 | AJ16: 2 | AK16: 2 | AL16: 2 | AM16: 0 | AN16: =IF(COUNTA(AB16:AD16)=0,"",SUM(AB16:AD16)) -> 6 | AO16: 8 | AP16: 4 | AQ16: 68.5 | AR16: cm | AS16: =IF(AQ16="","",IF(AR16="cm",AQ16,IF(AR16="inch",AQ16*2.54,""))) -> 68.5
A17: 16 | D17: 1 | E17: 61 | F17: =IF(E17="","",IF(E17<70,0,1)) -> 0 | G17: 2 | H17: 3 | I17: 2 | J17: 2 | K17: 0 | L17: 0 | M17: 0 | N17: 1 | O17: 0 | P17: 0 | Q17: 0 | R17: 1 | S17: 0 | T17: 0 | U17: 0 | W17: 4 | X17: 4 | Y17: 4 | Z17: 2 | AA17: 4 | AB17: 2 | AC17: 2 | AD17: 2 | AE17: 0 | AF17: 4 | AG17: 0 | AH17: 4 | AI17: 2 | AJ17: 2 | AK17: 2 | AL17: 4 | AM17: 2 | AN17: =IF(COUNTA(AB17:AD17)=0,"",SUM(AB17:AD17)) -> 6 | AO17: 12 | AP17: 8 | AQ17: 85.5 | AR17: cm | AS17: =IF(AQ17="","",IF(AR17="cm",AQ17,IF(AR17="inch",AQ17*2.54,""))) -> 85.5
A18: 17 | D18: 1 | E18: 63 | F18: =IF(E18="","",IF(E18<70,0,1)) -> 0 | G18: 2 | H18: 2 | I18: 3 | J18: 2 | K18: 1 | L18: 0 | M18: 0 | N18: 0 | O18: 1 | P18: 1 | Q18: 1 | R18: 1 | S18: 0 | T18: 0 | U18: 0 | W18: 4 | X18: 4 | Y18: 4 | Z18: 2 | AA18: 4 | AB18: 2 | AC18: 0 | AD18: 2 | AE18: 0 | AF18: 0 | AG18: 0 | AH18: 4 | AI18: 2 | AJ18: 2 | AK18: 2 | AL18: 2 | AM18: 0 | AN18: =IF(COUNTA(AB18:AD18)=0,"",SUM(AB18:AD18)) -> 4 | AO18: 8 | AP18: 4 | AQ18: 96 | AR18: cm | AS18: =IF(AQ18="","",IF(AR18="cm",AQ18,IF(AR18="inch",AQ18*2.54,""))) -> 96
A19: 18 | D19: 1 | E19: 63 | F19: =IF(E19="","",IF(E19<70,0,1)) -> 0 | G19: 2 | H19: 2 | I19: 3 | J19: 1 | K19: 1 | L19: 0 | M19: 0 | N19: 1 | O19: 0 | P19: 1 | Q19: 1 | R19: 1 | S19: 0 | T19: 0 | U19: 0 | W19: 4 | X19: 2 | Y19: 0 | Z19: 2 | AA19: 4 | AB19: 2 | AC19: 0 | AD19: 2 | AE19: 0 | AF19: 0 | AG19: 2 | AH19: 0 | AI19: 0 | AJ19: 2 | AK19: 2 | AL19: 2 | AM19: 0 | AN19: =IF(COUNTA(AB19:AD19)=0,"",SUM(AB19:AD19)) -> 4 | AO19: 4 | AP19: 4 | AQ19: 95 | AR19: cm | AS19: =IF(AQ19="","",IF(AR19="cm",AQ19,IF(AR19="inch",AQ19*2.54,""))) -> 95
A20: 19 | D20: 1 | E20: 67 | F20: =IF(E20="","",IF(E20<70,0,1)) -> 0 | G20: 2 | H20: 3 | I20: 1 | J20: 1 | K20: 1 | L20: 0 | M20: 0 | N20: 0 | O20: 1 | P20: 0 | Q20: 1 | R20: 1 | S20: 0 | T20: 0 | U20: 0 | W20: 3 | X20: 4 | Y20: 2 | Z20: 2 | AA20: 4 | AB20: 2 | AC20: 2 | AD20: 2 | AE20: 0 | AF20: 0 | AG20: 0 | AH20: 2 | AI20: 0 | AJ20: 0 | AK20: 4 | AL20: 4 | AM20: 0 | AN20: =IF(COUNTA(AB20:AD20)=0,"",SUM(AB20:AD20)) -> 6 | AO20: 2 | AP20: 8 | AQ20: 93 | AR20: cm | AS20: =IF(AQ20="","",IF(AR20="cm",AQ20,IF(AR20="inch",AQ20*2.54,""))) -> 93
A21: 20 | D21: 1 | E21: 66 | F21: =IF(E21="","",IF(E21<70,0,1)) -> 0 | G21: 2 | H21: 3 | I21: 2 | J21: 2 | K21: 0 | L21: 1 | M21: 0 | N21: 0 | O21: 0 | P21: 0 | Q21: 0 | R21: 0 | S21: 0 | T21: 0 | U21: 1 | V21: แพ้ฝุ่นละออง,สารเคมี | W21: 2 | X21: 2 | Y21: 2 | Z21: 2 | AA21: 2 | AB21: 2 | AC21: 2 | AD21: 2 | AE21: 0 | AF21: 0 | AG21: 2 | AH21: 0 | AI21: 0 | AJ21: 0 | AK21: 4 | AL21: 2 | AM21: 0 | AN21: =IF(COUNTA(AB21:AD21)=0,"",SUM(AB21:AD21)) -> 6 | AO21: 2 | AP21: 6 | AQ21: 81.5 | AR21: cm | AS21: =IF(AQ21="","",IF(AR21="cm",AQ21,IF(AR21="inch",AQ21*2.54,""))) -> 81.5
A22: 21 | D22: 1 | E22: 64 | F22: =IF(E22="","",IF(E22<70,0,1)) -> 0 | G22: 2 | H22: 1 | I22: 3 | J22: 1 | K22: 1 | L22: 0 | M22: 0 | N22: 0 | O22: 1 | P22: 0 | Q22: 0 | R22: 0 | S22: 0 | T22: 0 | U22: 1 | V22: ตับแข็ง ถุงลมโป่งพอง | W22: 4 | X22: 4 | Y22: 2 | Z22: 2 | AA22: 4 | AB22: 2 | AC22: 2 | AD22: 2 | AE22: 0 | AF22: 0 | AG22: 0 | AH22: 0 | AI22: 2 | AJ22: 2 | AK22: 2 | AL22: 2 | AM22: 0 | AN22: =IF(COUNTA(AB22:AD22)=0,"",SUM(AB22:AD22)) -> 6 | AO22: 4 | AP22: 4 | AQ22: 96 | AR22: cm | AS22: =IF(AQ22="","",IF(AR22="cm",AQ22,IF(AR22="inch",AQ22*2.54,""))) -> 96
A23: 22 | D23: 1 | E23: 69 | F23: =IF(E23="","",IF(E23<70,0,1)) -> 0 | G23: 2 | H23: 1 | I23: 3 | J23: 1 | K23: 1 | L23: 0 | M23: 0 | N23: 0 | O23: 0 | P23: 1 | Q23: 0 | R23: 1 | S23: 0 | T23: 0 | U23: 0 | V23: โลหิตจาง | W23: 1 | X23: 2 | Y23: 0 | Z23: 2 | AA23: 4 | AB23: 2 | AC23: 2 | AD23: 2 | AE23: 0 | AF23: 0 | AG23: 2 | AH23: 2 | AI23: 2 | AJ23: 2 | AK23: 2 | AL23: 2 | AM23: 0 | AN23: =IF(COUNTA(AB23:AD23)=0,"",SUM(AB23:AD23)) -> 6 | AO23: 8 | AP23: 4 | AQ23: 81.5 | AR23: cm | AS23: =IF(AQ23="","",IF(AR23="cm",AQ23,IF(AR23="inch",AQ23*2.54,""))) -> 81.5
A24: 23 | D24: 1 | E24: 63 | F24: =IF(E24="","",IF(E24<70,0,1)) -> 0 | G24: 1 | H24: 2 | I24: 2 | J24: 2 | K24: 1 | L24: 0 | M24: 0 | N24: 0 | O24: 1 | P24: 0 | Q24: 0 | R24: 0 | S24: 0 | T24: 0 | U24: 1 | V24: นิ่วในกรวยไต | W24: 4 | X24: 2 | Y24: 2 | Z24: 2 | AA24: 2 | AB24: 2 | AC24: 2 | AD24: 0 | AE24: 0 | AF24: 2 | AG24: 2 | AH24: 0 | AI24: 2 | AJ24: 0 | AK24: 2 | AL24: 2 | AM24: 0 | AN24: =IF(COUNTA(AB24:AD24)=0,"",SUM(AB24:AD24)) -> 4 | AO24: 6 | AP24: 4 | AQ24: 77.5 | AR24: cm | AS24: =IF(AQ24="","",IF(AR24="cm",AQ24,IF(AR24="inch",AQ24*2.54,""))) -> 77.5
A25: 24 | D25: 1 | E25: 65 | F25: =IF(E25="","",IF(E25<70,0,1)) -> 0 | G25: 2 | H25: 3 | I25: 2 | J25: 1 | K25: 1 | L25: 0 | M25: 0 | N25: 0 | O25: 1 | P25: 0 | Q25: 1 | R25: 1 | S25: 0 | T25: 0 | U25: 0 | W25: 4 | X25: 2 | Y25: 2 | Z25: 2 | AA25: 4 | AB25: 2 | AC25: 2 | AD25: 2 | AE25: 0 | AF25: 0 | AG25: 0 | AH25: 0 | AI25: 2 | AJ25: 2 | AK25: 2 | AL25: 2 | AM25: 0 | AN25: =IF(COUNTA(AB25:AD25)=0,"",SUM(AB25:AD25)) -> 6 | AO25: 4 | AP25: 4 | AQ25: 88 | AR25: cm | AS25: =IF(AQ25="","",IF(AR25="cm",AQ25,IF(AR25="inch",AQ25*2.54,""))) -> 88
A26: 25 | D26: 1 | E26: 63 | F26: =IF(E26="","",IF(E26<70,0,1)) -> 0 | G26: 2 | H26: 2 | I26: 2 | J26: 1 | K26: 1 | L26: 0 | M26: 0 | N26: 0 | O26: 0 | P26: 0 | Q26: 0 | R26: 1 | S26: 0 | T26: 0 | U26: 0 | W26: 4 | X26: 0 | Y26: 0 | Z26: 2 | AA26: 4 | AB26: 2 | AC26: 0 | AD26: 2 | AE26: 0 | AF26: 0 | AG26: 4 | AH26: 2 | AI26: 2 | AJ26: 2 | AK26: 2 | AL26: 4 | AM26: 0 | AN26: =IF(COUNTA(AB26:AD26)=0,"",SUM(AB26:AD26)) -> 4 | AO26: 10 | AP26: 6 | AQ26: 98 | AR26: cm | AS26: =IF(AQ26="","",IF(AR26="cm",AQ26,IF(AR26="inch",AQ26*2.54,""))) -> 98
A27: 26 | D27: 1 | E27: 69 | F27: =IF(E27="","",IF(E27<70,0,1)) -> 0 | G27: 2 | H27: 1 | I27: 2 | J27: 1 | K27: 1 | L27: 0 | M27: 0 | N27: 0 | O27: 0 | P27: 0 | Q27: 1 | R27: 1 | S27: 0 | T27: 0 | U27: 0 | W27: 4 | X27: 2 | Y27: 2 | Z27: 2 | AA27: 4 | AB27: 2 | AC27: 0 | AD27: 2 | AE27: 0 | AF27: 0 | AG27: 0 | AH27: 0 | AI27: 2 | AJ27: 0 | AK27: 2 | AL27: 2 | AM27: 0 | AN27: =IF(COUNTA(AB27:AD27)=0,"",SUM(AB27:AD27)) -> 4 | AO27: 2 | AP27: 4 | AQ27: 76 | AR27: cm | AS27: =IF(AQ27="","",IF(AR27="cm",AQ27,IF(AR27="inch",AQ27*2.54,""))) -> 76
A28: 27 | D28: 1 | E28: 68 | F28: =IF(E28="","",IF(E28<70,0,1)) -> 0 | G28: 2 | H28: 1 | I28: 2 | J28: 1 | K28: 1 | L28: 0 | M28: 0 | N28: 0 | O28: 0 | P28: 0 | Q28: 0 | R28: 0 | S28: 0 | T28: 0 | U28: 1 | V28: ไมเกรน | W28: 4 | X28: 2 | Y28: 2 | Z28: 2 | AA28: 4 | AB28: 2 | AC28: 2 | AD28: 2 | AE28: 0 | AF28: 0 | AG28: 2 | AH28: 0 | AI28: 2 | AJ28: 0 | AK28: 2 | AL28: 2 | AM28: 0 | AN28: =IF(COUNTA(AB28:AD28)=0,"",SUM(AB28:AD28)) -> 6 | AO28: 4 | AP28: 4 | AQ28: 99.5 | AR28: cm | AS28: =IF(AQ28="","",IF(AR28="cm",AQ28,IF(AR28="inch",AQ28*2.54,""))) -> 99.5
A29: 28 | D29: 1 | E29: 66 | F29: =IF(E29="","",IF(E29<70,0,1)) -> 0 | G29: 2 | H29: 2 | I29: 2 | J29: 1 | K29: 1 | L29: 0 | M29: 0 | N29: 0 | O29: 0 | P29: 0 | Q29: 1 | R29: 1 | S29: 0 | T29: 0 | U29: 0 | W29: 4 | X29: 4 | Y29: 2 | Z29: 0 | AA29: 4 | AB29: 2 | AC29: 0 | AD29: 2 | AE29: 2 | AF29: 4 | AG29: 2 | AH29: 0 | AI29: 2 | AJ29: 0 | AK29: 4 | AL29: 4 | AM29: 0 | AN29: =IF(COUNTA(AB29:AD29)=0,"",SUM(AB29:AD29)) -> 4 | AO29: 10 | AP29: 8 | AQ29: 95 | AR29: cm | AS29: =IF(AQ29="","",IF(AR29="cm",AQ29,IF(AR29="inch",AQ29*2.54,""))) -> 95
A30: 29 | D30: 1 | E30: 66 | F30: =IF(E30="","",IF(E30<70,0,1)) -> 0 | G30: 1 | H30: 2 | I30: 2 | J30: 1 | K30: 1 | L30: 0 | M30: 0 | N30: 0 | O30: 0 | P30: 0 | Q30: 0 | R30: 0 | S30: 0 | T30: 0 | U30: 1 | V30: ต่อมลูกหมากโต | W30: 2 | X30: 4 | Y30: 2 | Z30: 2 | AA30: 2 | AB30: 2 | AC30: 2 | AD30: 2 | AE30: 4 | AF30: 2 | AG30: 0 | AH30: 0 | AI30: 0 | AJ30: 2 | AK30: 2 | AL30: 2 | AM30: 4 | AN30: =IF(COUNTA(AB30:AD30)=0,"",SUM(AB30:AD30)) -> 6 | AO30: 8 | AP30: 8 | AQ30: 108 | AR30: cm | AS30: =IF(AQ30="","",IF(AR30="cm",AQ30,IF(AR30="inch",AQ30*2.54,""))) -> 108
A31: 30 | D31: 1 | E31: 67 | F31: =IF(E31="","",IF(E31<70,0,1)) -> 0 | G31: 2 | H31: 1 | I31: 3 | J31: 1 | K31: 1 | L31: 0 | M31: 0 | N31: 1 | O31: 0 | P31: 0 | Q31: 1 | R31: 1 | S31: 0 | T31: 0 | U31: 0 | W31: 4 | X31: 2 | Y31: 2 | Z31: 2 | AA31: 4 | AB31: 2 | AC31: 2 | AD31: 2 | AE31: 0 | AF31: 2 | AG31: 2 | AH31: 0 | AI31: 2 | AJ31: 2 | AK31: 2 | AL31: 2 | AM31: 0 | AN31: =IF(COUNTA(AB31:AD31)=0,"",SUM(AB31:AD31)) -> 6 | AO31: 8 | AP31: 4 | AQ31: 99 | AR31: cm | AS31: =IF(AQ31="","",IF(AR31="cm",AQ31,IF(AR31="inch",AQ31*2.54,""))) -> 99
A32: 31 | D32: 1 | E32: 63 | F32: =IF(E32="","",IF(E32<70,0,1)) -> 0 | G32: 2 | H32: 2 | I32: 1 | J32: 1 | K32: 1 | L32: 0 | M32: 0 | N32: 0 | O32: 0 | P32: 0 | Q32: 0 | R32: 0 | S32: 0 | T32: 0 | U32: 1 | V32: ภูมิแพ้อากาศ | W32: 1 | X32: 2 | Y32: 2 | Z32: 2 | AA32: 2 | AB32: 2 | AC32: 0 | AD32: 2 | AE32: 0 | AF32: 0 | AG32: 0 | AH32: 2 | AI32: 0 | AJ32: 0 | AK32: 2 | AL32: 2 | AM32: 0 | AN32: =IF(COUNTA(AB32:AD32)=0,"",SUM(AB32:AD32)) -> 4 | AO32: 2 | AP32: 4 | AQ32: 71 | AR32: cm | AS32: =IF(AQ32="","",IF(AR32="cm",AQ32,IF(AR32="inch",AQ32*2.54,""))) -> 71
A33: 32 | D33: 1 | E33: 63 | F33: =IF(E33="","",IF(E33<70,0,1)) -> 0 | G33: 1 | H33: 3 | I33: 2 | J33: 2 | K33: 1 | L33: 0 | M33: 0 | N33: 0 | O33: 1 | P33: 0 | Q33: 0 | R33: 0 | S33: 0 | T33: 0 | U33: 1 | V33: ภูมิแพ้อากาศ | W33: 2 | X33: 2 | Y33: 2 | Z33: 2 | AA33: 2 | AB33: 2 | AC33: 2 | AD33: 2 | AE33: 0 | AF33: 2 | AG33: 2 | AH33: 2 | AI33: 2 | AJ33: 2 | AK33: 2 | AL33: 4 | AM33: 0 | AN33: =IF(COUNTA(AB33:AD33)=0,"",SUM(AB33:AD33)) -> 6 | AO33: 10 | AP33: 6 | AQ33: 101 | AR33: cm | AS33: =IF(AQ33="","",IF(AR33="cm",AQ33,IF(AR33="inch",AQ33*2.54,""))) -> 101
A34: 33 | D34: 1 | E34: 68 | F34: =IF(E34="","",IF(E34<70,0,1)) -> 0 | G34: 2 | H34: 4 | I34: 2 | J34: 4 | K34: 0 | L34: 1 | M34: 0 | N34: 0 | O34: 0 | P34: 0 | Q34: 0 | R34: 0 | S34: 0 | T34: 0 | U34: 1 | V34: ไทรอยด์ | W34: 1 | X34: 2 | Y34: 2 | Z34: 2 | AA34: 2 | AB34: 2 | AC34: 2 | AD34: 2 | AE34: 0 | AF34: 0 | AG34: 2 | AH34: 2 | AI34: 2 | AJ34: 2 | AK34: 2 | AL34: 4 | AM34: 2 | AN34: =IF(COUNTA(AB34:AD34)=0,"",SUM(AB34:AD34)) -> 6 | AO34: 8 | AP34: 8 | AQ34: 86.5 | AR34: cm | AS34: =IF(AQ34="","",IF(AR34="cm",AQ34,IF(AR34="inch",AQ34*2.54,""))) -> 86.5
A35: 34 | D35: 1 | E35: 64 | F35: =IF(E35="","",IF(E35<70,0,1)) -> 0 | G35: 2 | H35: 2 | I35: 2 | J35: 3 | K35: 0 | L35: 0 | M35: 1 | N35: 0 | O35: 0 | P35: 0 | Q35: 0 | R35: 0 | S35: 0 | T35: 0 | U35: 0 | V35: ไม่มีโรค | W35: 4 | X35: 2 | Y35: 2 | Z35: 2 | AA35: 2 | AB35: 2 | AC35: 2 | AD35: 2 | AE35: 0 | AF35: 0 | AG35: 2 | AH35: 2 | AI35: 2 | AJ35: 2 | AK35: 2 | AL35: 2 | AM35: 0 | AN35: =IF(COUNTA(AB35:AD35)=0,"",SUM(AB35:AD35)) -> 6 | AO35: 8 | AP35: 4 | AQ35: 84 | AR35: cm | AS35: =IF(AQ35="","",IF(AR35="cm",AQ35,IF(AR35="inch",AQ35*2.54,""))) -> 84
A36: 35 | D36: 1 | E36: 69 | F36: =IF(E36="","",IF(E36<70,0,1)) -> 0 | G36: 2 | H36: 2 | I36: 2 | J36: 2 | K36: 0 | L36: 0 | M36: 0 | N36: 1 | O36: 0 | P36: 0 | Q36: 1 | R36: 1 | S36: 0 | T36: 0 | U36: 0 | W36: 2 | X36: 2 | Y36: 2 | Z36: 2 | AA36: 4 | AB36: 2 | AC36: 2 | AD36: 2 | AE36: 0 | AF36: 0 | AG36: 2 | AH36: 0 | AI36: 0 | AJ36: 2 | AK36: 4 | AL36: 2 | AM36: 0 | AN36: =IF(COUNTA(AB36:AD36)=0,"",SUM(AB36:AD36)) -> 6 | AO36: 4 | AP36: 6 | AQ36: 85 | AR36: cm | AS36: =IF(AQ36="","",IF(AR36="cm",AQ36,IF(AR36="inch",AQ36*2.54,""))) -> 85
A37: 36 | D37: 1 | E37: 66 | F37: =IF(E37="","",IF(E37<70,0,1)) -> 0 | G37: 2 | H37: 4 | I37: 1 | J37: 4 | K37: 0 | L37: 0 | M37: 0 | N37: 0 | O37: 1 | P37: 1 | Q37: 0 | R37: 0 | S37: 0 | T37: 0 | U37: 0 | W37: 1 | X37: 2 | Y37: 2 | Z37: 2 | AA37: 4 | AB37: 2 | AC37: 2 | AD37: 2 | AE37: 0 | AF37: 0 | AG37: 2 | AH37: 0 | AI37: 0 | AJ37: 2 | AK37: 2 | AL37: 2 | AM37: 0 | AN37: =IF(COUNTA(AB37:AD37)=0,"",SUM(AB37:AD37)) -> 6 | AO37: 4 | AP37: 4 | AQ37: 91 | AR37: cm | AS37: =IF(AQ37="","",IF(AR37="cm",AQ37,IF(AR37="inch",AQ37*2.54,""))) -> 91
A38: 37 | D38: 1 | E38: 61 | F38: =IF(E38="","",IF(E38<70,0,1)) -> 0 | G38: 2 | H38: 2 | I38: 1 | J38: 4 | K38: 0 | L38: 0 | M38: 0 | N38: 0 | O38: 1 | P38: 1 | Q38: 1 | R38: 1 | S38: 0 | T38: 0 | U38: 0 | W38: 4 | X38: 2 | Y38: 2 | Z38: 2 | AA38: 4 | AB38: 2 | AC38: 2 | AD38: 2 | AE38: 0 | AF38: 0 | AG38: 2 | AH38: 0 | AI38: 0 | AJ38: 2 | AK38: 2 | AL38: 2 | AM38: 0 | AN38: =IF(COUNTA(AB38:AD38)=0,"",SUM(AB38:AD38)) -> 6 | AO38: 4 | AP38: 4 | AQ38: 104.5 | AR38: cm | AS38: =IF(AQ38="","",IF(AR38="cm",AQ38,IF(AR38="inch",AQ38*2.54,""))) -> 104.5
A39: 38 | D39: 1 | E39: 61 | F39: =IF(E39="","",IF(E39<70,0,1)) -> 0 | G39: 2 | H39: 1 | I39: 2 | J39: 2 | K39: 0 | L39: 0 | M39: 0 | N39: 0 | O39: 1 | P39: 0 | Q39: 0 | R39: 1 | S39: 0 | T39: 0 | U39: 0 | W39: 2 | X39: 2 | Y39: 2 | Z39: 2 | AA39: 4 | AB39: 2 | AC39: 2 | AD39: 2 | AE39: 0 | AF39: 0 | AG39: 0 | AH39: 0 | AI39: 0 | AJ39: 2 | AK39: 2 | AL39: 2 | AM39: 0 | AN39: =IF(COUNTA(AB39:AD39)=0,"",SUM(AB39:AD39)) -> 6 | AO39: 2 | AP39: 4 | AQ39: 105.5 | AR39: cm | AS39: =IF(AQ39="","",IF(AR39="cm",AQ39,IF(AR39="inch",AQ39*2.54,""))) -> 105.5
A40: 39 | D40: 1 | E40: 66 | F40: =IF(E40="","",IF(E40<70,0,1)) -> 0 | G40: 2 | H40: 1 | I40: 1 | J40: 1 | K40: 1 | L40: 0 | M40: 0 | N40: 0 | O40: 0 | P40: 0 | Q40: 1 | R40: 1 | S40: 0 | T40: 0 | U40: 0 | W40: 1 | X40: 0 | Y40: 0 | Z40: 2 | AA40: 4 | AB40: 2 | AC40: 2 | AD40: 2 | AE40: 0 | AF40: 0 | AG40: 0 | AH40: 0 | AI40: 0 | AJ40: 0 | AK40: 2 | AL40: 4 | AM40: 0 | AN40: =IF(COUNTA(AB40:AD40)=0,"",SUM(AB40:AD40)) -> 6 | AO40: 0 | AP40: 6 | AQ40: 79 | AR40: cm | AS40: =IF(AQ40="","",IF(AR40="cm",AQ40,IF(AR40="inch",AQ40*2.54,""))) -> 79
...

Sheet Prediction
A1: record_id | B1: assessment_id | C1: assessment_date | D1: age_group01 | E1: D2_total | F1: D3_total | G1: wc_cm | H1: L_Over | I1: L_Normal | J1: EXP_over | K1: EXP_normal | L1: Denom | M1: P_Under | N1: P_Over | O1: P_Normal | P1: predicted_group
A2: =IF(Participant_Data!A2="","",Participant_Data!A2) -> 1 | B2: =IF(Participant_Data!B2="","",Participant_Data!B2) | C2: =IF(Participant_Data!C2="","",Participant_Data!C2) | D2: =IF(Participant_Data!F2="","",Participant_Data!F2) -> 0 | E2: =IF(Participant_Data!AO2="","",Participant_Data!AO2) -> 8 | F2: =IF(Participant_Data!AP2="","",Participant_Data!AP2) -> 4 | G2: =IF(Participant_Data!AS2="","",Participant_Data!AS2) -> 97 | H2: =IF(OR(D2="",E2="",F2="",G2=""),"", -23.625 + 0.019*E2 - 0.377*F2 + 0.349*G2 - 2.336*D2) -> 8.872 | I2: =IF(OR(D2="",E2="",F2="",G2=""),"", -9.655 + 0.039*E2 - 0.507*F2 + 0.189*G2 - 2.489*D2) -> 6.962 | J2: =IF(H2="","",EXP(H2)) -> 7129.5258 | K2: =IF(I2="","",EXP(I2)) -> 1055.7429 | L2: =IF(OR(J2="",K2=""),"",1+J2+K2) -> 8186.2687 | M2: =IF(L2="","",1/L2) -> 0.00012215578 | N2: =IF(L2="","",J2/L2) -> 0.87091275 | O2: =IF(L2="","",K2/L2) -> 0.1289651 | P2: =IF(OR(M2="",N2="",O2=""),"",IF(M2=MAX(M2:O2),"Under",IF(N2=MAX(M2:O2),"Over","Normal"))) -> Over
A3: =IF(Participant_Data!A3="","",Participant_Data!A3) -> 2 | B3: =IF(Participant_Data!B3="","",Participant_Data!B3) | C3: =IF(Participant_Data!C3="","",Participant_Data!C3) | D3: =IF(Participant_Data!F3="","",Participant_Data!F3) -> 0 | E3: =IF(Participant_Data!AO3="","",Participant_Data!AO3) -> 12 | F3: =IF(Participant_Data!AP3="","",Participant_Data!AP3) -> 4 | G3: =IF(Participant_Data!AS3="","",Participant_Data!AS3) -> 72 | H3: =IF(OR(D3="",E3="",F3="",G3=""),"", -23.625 + 0.019*E3 - 0.377*F3 + 0.349*G3 - 2.336*D3) -> 0.223 | I3: =IF(OR(D3="",E3="",F3="",G3=""),"", -9.655 + 0.039*E3 - 0.507*F3 + 0.189*G3 - 2.489*D3) -> 2.393 | J3: =IF(H3="","",EXP(H3)) -> 1.2498206 | K3: =IF(I3="","",EXP(I3)) -> 10.946284 | L3: =IF(OR(J3="",K3=""),"",1+J3+K3) -> 13.196104 | M3: =IF(L3="","",1/L3) -> 0.075779941 | N3: =IF(L3="","",J3/L3) -> 0.09471133 | O3: =IF(L3="","",K3/L3) -> 0.82950873 | P3: =IF(OR(M3="",N3="",O3=""),"",IF(M3=MAX(M3:O3),"Under",IF(N3=MAX(M3:O3),"Over","Normal"))) -> Normal
A4: =IF(Participant_Data!A4="","",Participant_Data!A4) -> 3 | B4: =IF(Participant_Data!B4="","",Participant_Data!B4) | C4: =IF(Participant_Data!C4="","",Participant_Data!C4) | D4: =IF(Participant_Data!F4="","",Participant_Data!F4) -> 0 | E4: =IF(Participant_Data!AO4="","",Participant_Data!AO4) -> 4 | F4: =IF(Participant_Data!AP4="","",Participant_Data!AP4) -> 6 | G4: =IF(Participant_Data!AS4="","",Participant_Data!AS4) -> 68 | H4: =IF(OR(D4="",E4="",F4="",G4=""),"", -23.625 + 0.019*E4 - 0.377*F4 + 0.349*G4 - 2.336*D4) -> -2.079 | I4: =IF(OR(D4="",E4="",F4="",G4=""),"", -9.655 + 0.039*E4 - 0.507*F4 + 0.189*G4 - 2.489*D4) -> 0.311 | J4: =IF(H4="","",EXP(H4)) -> 0.1250552 | K4: =IF(I4="","",EXP(I4)) -> 1.3647892 | L4: =IF(OR(J4="",K4=""),"",1+J4+K4) -> 2.4898444 | M4: =IF(L4="","",1/L4) -> 0.40163152 | N4: =IF(L4="","",J4/L4) -> 0.050226112 | O4: =IF(L4="","",K4/L4) -> 0.54814237 | P4: =IF(OR(M4="",N4="",O4=""),"",IF(M4=MAX(M4:O4),"Under",IF(N4=MAX(M4:O4),"Over","Normal"))) -> Normal
A5: =IF(Participant_Data!A5="","",Participant_Data!A5) -> 4 | B5: =IF(Participant_Data!B5="","",Participant_Data!B5) | C5: =IF(Participant_Data!C5="","",Participant_Data!C5) | D5: =IF(Participant_Data!F5="","",Participant_Data!F5) -> 0 | E5: =IF(Participant_Data!AO5="","",Participant_Data!AO5) -> 4 | F5: =IF(Participant_Data!AP5="","",Participant_Data!AP5) -> 6 | G5: =IF(Participant_Data!AS5="","",Participant_Data!AS5) -> 59 | H5: =IF(OR(D5="",E5="",F5="",G5=""),"", -23.625 + 0.019*E5 - 0.377*F5 + 0.349*G5 - 2.336*D5) -> -5.22 | I5: =IF(OR(D5="",E5="",F5="",G5=""),"", -9.655 + 0.039*E5 - 0.507*F5 + 0.189*G5 - 2.489*D5) -> -1.39 | J5: =IF(H5="","",EXP(H5)) -> 0.0054073291 | K5: =IF(I5="","",EXP(I5)) -> 0.2490753 | L5: =IF(OR(J5="",K5=""),"",1+J5+K5) -> 1.2544826 | M5: =IF(L5="","",1/L5) -> 0.79714137 | N5: =IF(L5="","",J5/L5) -> 0.0043104057 | O5: =IF(L5="","",K5/L5) -> 0.19854823 | P5: =IF(OR(M5="",N5="",O5=""),"",IF(M5=MAX(M5:O5),"Under",IF(N5=MAX(M5:O5),"Over","Normal"))) -> Under
A6: =IF(Participant_Data!A6="","",Participant_Data!A6) -> 5 | B6: =IF(Participant_Data!B6="","",Participant_Data!B6) | C6: =IF(Participant_Data!C6="","",Participant_Data!C6) | D6: =IF(Participant_Data!F6="","",Participant_Data!F6) -> 0 | E6: =IF(Participant_Data!AO6="","",Participant_Data!AO6) -> 8 | F6: =IF(Participant_Data!AP6="","",Participant_Data!AP6) -> 4 | G6: =IF(Participant_Data!AS6="","",Participant_Data!AS6) -> 88 | H6: =IF(OR(D6="",E6="",F6="",G6=""),"", -23.625 + 0.019*E6 - 0.377*F6 + 0.349*G6 - 2.336*D6) -> 5.731 | I6: =IF(OR(D6="",E6="",F6="",G6=""),"", -9.655 + 0.039*E6 - 0.507*F6 + 0.189*G6 - 2.489*D6) -> 5.261 | J6: =IF(H6="","",EXP(H6)) -> 308.27739 | K6: =IF(I6="","",EXP(I6)) -> 192.67407 | L6: =IF(OR(J6="",K6=""),"",1+J6+K6) -> 501.95146 | M6: =IF(L6="","",1/L6) -> 0.0019922245 | N6: =IF(L6="","",J6/L6) -> 0.61415777 | O6: =IF(L6="","",K6/L6) -> 0.38385 | P6: =IF(OR(M6="",N6="",O6=""),"",IF(M6=MAX(M6:O6),"Under",IF(N6=MAX(M6:O6),"Over","Normal"))) -> Over
A7: =IF(Participant_Data!A7="","",Participant_Data!A7) -> 6 | B7: =IF(Participant_Data!B7="","",Participant_Data!B7) | C7: =IF(Participant_Data!C7="","",Participant_Data!C7) | D7: =IF(Participant_Data!F7="","",Participant_Data!F7) -> 0 | E7: =IF(Participant_Data!AO7="","",Participant_Data!AO7) -> 2 | F7: =IF(Participant_Data!AP7="","",Participant_Data!AP7) -> 4 | G7: =IF(Participant_Data!AS7="","",Participant_Data!AS7) -> 77 | H7: =IF(OR(D7="",E7="",F7="",G7=""),"", -23.625 + 0.019*E7 - 0.377*F7 + 0.349*G7 - 2.336*D7) -> 1.778 | I7: =IF(OR(D7="",E7="",F7="",G7=""),"", -9.655 + 0.039*E7 - 0.507*F7 + 0.189*G7 - 2.489*D7) -> 2.948 | J7: =IF(H7="","",EXP(H7)) -> 5.9180086 | K7: =IF(I7="","",EXP(I7)) -> 19.06778 | L7: =IF(OR(J7="",K7=""),"",1+J7+K7) -> 25.985789 | M7: =IF(L7="","",1/L7) -> 0.038482573 | N7: =IF(L7="","",J7/L7) -> 0.2277402 | O7: =IF(L7="","",K7/L7) -> 0.73377723 | P7: =IF(OR(M7="",N7="",O7=""),"",IF(M7=MAX(M7:O7),"Under",IF(N7=MAX(M7:O7),"Over","Normal"))) -> Normal
A8: =IF(Participant_Data!A8="","",Participant_Data!A8) -> 7 | B8: =IF(Participant_Data!B8="","",Participant_Data!B8) | C8: =IF(Participant_Data!C8="","",Participant_Data!C8) | D8: =IF(Participant_Data!F8="","",Participant_Data!F8) -> 0 | E8: =IF(Participant_Data!AO8="","",Participant_Data!AO8) -> 6 | F8: =IF(Participant_Data!AP8="","",Participant_Data!AP8) -> 4 | G8: =IF(Participant_Data!AS8="","",Participant_Data!AS8) -> 94.5 | H8: =IF(OR(D8="",E8="",F8="",G8=""),"", -23.625 + 0.019*E8 - 0.377*F8 + 0.349*G8 - 2.336*D8) -> 7.9615 | I8: =IF(OR(D8="",E8="",F8="",G8=""),"", -9.655 + 0.039*E8 - 0.507*F8 + 0.189*G8 - 2.489*D8) -> 6.4115 | J8: =IF(H8="","",EXP(H8)) -> 2868.3723 | K8: =IF(I8="","",EXP(I8)) -> 608.80621 | L8: =IF(OR(J8="",K8=""),"",1+J8+K8) -> 3478.1785 | M8: =IF(L8="","",1/L8) -> 0.00028750681 | N8: =IF(L8="","",J8/L8) -> 0.82467656 | O8: =IF(L8="","",K8/L8) -> 0.17503593 | P8: =IF(OR(M8="",N8="",O8=""),"",IF(M8=MAX(M8:O8),"Under",IF(N8=MAX(M8:O8),"Over","Normal"))) -> Over
A9: =IF(Participant_Data!A9="","",Participant_Data!A9) -> 8 | B9: =IF(Participant_Data!B9="","",Participant_Data!B9) | C9: =IF(Participant_Data!C9="","",Participant_Data!C9) | D9: =IF(Participant_Data!F9="","",Participant_Data!F9) -> 0 | E9: =IF(Participant_Data!AO9="","",Participant_Data!AO9) -> 4 | F9: =IF(Participant_Data!AP9="","",Participant_Data!AP9) -> 6 | G9: =IF(Participant_Data!AS9="","",Participant_Data!AS9) -> 95.5 | H9: =IF(OR(D9="",E9="",F9="",G9=""),"", -23.625 + 0.019*E9 - 0.377*F9 + 0.349*G9 - 2.336*D9) -> 7.5185 | I9: =IF(OR(D9="",E9="",F9="",G9=""),"", -9.655 + 0.039*E9 - 0.507*F9 + 0.189*G9 - 2.489*D9) -> 5.5085 | J9: =IF(H9="","",EXP(H9)) -> 1841.8025 | K9: =IF(I9="","",EXP(I9)) -> 246.78068 | L9: =IF(OR(J9="",K9=""),"",1+J9+K9) -> 2089.5832 | M9: =IF(L9="","",1/L9) -> 0.00047856434 | N9: =IF(L9="","",J9/L9) -> 0.881421 | O9: =IF(L9="","",K9/L9) -> 0.11810043 | P9: =IF(OR(M9="",N9="",O9=""),"",IF(M9=MAX(M9:O9),"Under",IF(N9=MAX(M9:O9),"Over","Normal"))) -> Over
A10: =IF(Participant_Data!A10="","",Participant_Data!A10) -> 9 | B10: =IF(Participant_Data!B10="","",Participant_Data!B10) | C10: =IF(Participant_Data!C10="","",Participant_Data!C10) | D10: =IF(Participant_Data!F10="","",Participant_Data!F10) -> 0 | E10: =IF(Participant_Data!AO10="","",Participant_Data!AO10) -> 8 | F10: =IF(Participant_Data!AP10="","",Participant_Data!AP10) -> 4 | G10: =IF(Participant_Data!AS10="","",Participant_Data!AS10) -> 80 | H10: =IF(OR(D10="",E10="",F10="",G10=""),"", -23.625 + 0.019*E10 - 0.377*F10 + 0.349*G10 - 2.336*D10) -> 2.939 | I10: =IF(OR(D10="",E10="",F10="",G10=""),"", -9.655 + 0.039*E10 - 0.507*F10 + 0.189*G10 - 2.489*D10) -> 3.749 | J10: =IF(H10="","",EXP(H10)) -> 18.89694 | K10: =IF(I10="","",EXP(I10)) -> 42.478582 | L10: =IF(OR(J10="",K10=""),"",1+J10+K10) -> 62.375522 | M10: =IF(L10="","",1/L10) -> 0.01603193 | N10: =IF(L10="","",J10/L10) -> 0.30295442 | O10: =IF(L10="","",K10/L10) -> 0.68101365 | P10: =IF(OR(M10="",N10="",O10=""),"",IF(M10=MAX(M10:O10),"Under",IF(N10=MAX(M10:O10),"Over","Normal"))) -> Normal
A11: =IF(Participant_Data!A11="","",Participant_Data!A11) -> 10 | B11: =IF(Participant_Data!B11="","",Participant_Data!B11) | C11: =IF(Participant_Data!C11="","",Participant_Data!C11) | D11: =IF(Participant_Data!F11="","",Participant_Data!F11) -> 0 | E11: =IF(Participant_Data!AO11="","",Participant_Data!AO11) -> 4 | F11: =IF(Participant_Data!AP11="","",Participant_Data!AP11) -> 4 | G11: =IF(Participant_Data!AS11="","",Participant_Data!AS11) -> 79.5 | H11: =IF(OR(D11="",E11="",F11="",G11=""),"", -23.625 + 0.019*E11 - 0.377*F11 + 0.349*G11 - 2.336*D11) -> 2.6885 | I11: =IF(OR(D11="",E11="",F11="",G11=""),"", -9.655 + 0.039*E11 - 0.507*F11 + 0.189*G11 - 2.489*D11) -> 3.4985 | J11: =IF(H11="","",EXP(H11)) -> 14.709595 | K11: =IF(I11="","",EXP(I11)) -> 33.065816 | L11: =IF(OR(J11="",K11=""),"",1+J11+K11) -> 48.775411 | M11: =IF(L11="","",1/L11) -> 0.020502134 | N11: =IF(L11="","",J11/L11) -> 0.30157808 | O11: =IF(L11="","",K11/L11) -> 0.67791978 | P11: =IF(OR(M11="",N11="",O11=""),"",IF(M11=MAX(M11:O11),"Under",IF(N11=MAX(M11:O11),"Over","Normal"))) -> Normal
A12: =IF(Participant_Data!A12="","",Participant_Data!A12) -> 11 | B12: =IF(Participant_Data!B12="","",Participant_Data!B12) | C12: =IF(Participant_Data!C12="","",Participant_Data!C12) | D12: =IF(Participant_Data!F12="","",Participant_Data!F12) -> 0 | E12: =IF(Participant_Data!AO12="","",Participant_Data!AO12) -> 8 | F12: =IF(Participant_Data!AP12="","",Participant_Data!AP12) -> 4 | G12: =IF(Participant_Data!AS12="","",Participant_Data!AS12) -> 84 | H12: =IF(OR(D12="",E12="",F12="",G12=""),"", -23.625 + 0.019*E12 - 0.377*F12 + 0.349*G12 - 2.336*D12) -> 4.335 | I12: =IF(OR(D12="",E12="",F12="",G12=""),"", -9.655 + 0.039*E12 - 0.507*F12 + 0.189*G12 - 2.489*D12) -> 4.505 | J12: =IF(H12="","",EXP(H12)) -> 76.324959 | K12: =IF(I12="","",EXP(I12)) -> 90.468344 | L12: =IF(OR(J12="",K12=""),"",1+J12+K12) -> 167.7933 | M12: =IF(L12="","",1/L12) -> 0.0059597134 | N12: =IF(L12="","",J12/L12) -> 0.45487488 | O12: =IF(L12="","",K12/L12) -> 0.5391654 | P12: =IF(OR(M12="",N12="",O12=""),"",IF(M12=MAX(M12:O12),"Under",IF(N12=MAX(M12:O12),"Over","Normal"))) -> Normal
A13: =IF(Participant_Data!A13="","",Participant_Data!A13) -> 12 | B13: =IF(Participant_Data!B13="","",Participant_Data!B13) | C13: =IF(Participant_Data!C13="","",Participant_Data!C13) | D13: =IF(Participant_Data!F13="","",Participant_Data!F13) -> 0 | E13: =IF(Participant_Data!AO13="","",Participant_Data!AO13) -> 10 | F13: =IF(Participant_Data!AP13="","",Participant_Data!AP13) -> 4 | G13: =IF(Participant_Data!AS13="","",Participant_Data!AS13) -> 83 | H13: =IF(OR(D13="",E13="",F13="",G13=""),"", -23.625 + 0.019*E13 - 0.377*F13 + 0.349*G13 - 2.336*D13) -> 4.024 | I13: =IF(OR(D13="",E13="",F13="",G13=""),"", -9.655 + 0.039*E13 - 0.507*F13 + 0.189*G13 - 2.489*D13) -> 4.394 | J13: =IF(H13="","",EXP(H13)) -> 55.924356 | K13: =IF(I13="","",EXP(I13)) -> 80.963627 | L13: =IF(OR(J13="",K13=""),"",1+J13+K13) -> 137.88798 | M13: =IF(L13="","",1/L13) -> 0.0072522636 | N13: =IF(L13="","",J13/L13) -> 0.40557817 | O13: =IF(L13="","",K13/L13) -> 0.58716956 | P13: =IF(OR(M13="",N13="",O13=""),"",IF(M13=MAX(M13:O13),"Under",IF(N13=MAX(M13:O13),"Over","Normal"))) -> Normal
... A301: =IF(Participant_Data!A301="","",Participant_Data!A301) -> 300 | B301: =IF(Participant_Data!B301="","",Participant_Data!B301) | C301: =IF(Participant_Data!C301="","",Participant_Data!C301) | D301: =IF(Participant_Data!F301="","",Participant_Data!F301) | E301: =IF(Participant_Data!AO301="","",Participant_Data!AO301) | F301: =IF(Participant_Data!AP301="","",Participant_Data!AP301) | G301: =IF(Participant_Data!AS301="","",Participant_Data!AS301) | H301: =IF(OR(D301="",E301="",F301="",G301=""),"", -23.625 + 0.019*E301 - 0.377*F301 + 0.349*G301 - 2.336*D301) | I301: =IF(OR(D301="",E301="",F301="",G301=""),"", -9.655 + 0.039*E301 - 0.507*F301 + 0.189*G301 - 2.489*D301) | J301: =IF(H301="","",EXP(H301)) | K301: =IF(I301="","",EXP(I301)) | L301: =IF(OR(J301="",K301=""),"",1+J301+K301) | M301: =IF(L301="","",1/L301) | N301: =IF(L301="","",J301/L301) | O301: =IF(L301="","",K301/L301) | P301: =IF(OR(M301="",N301="",O301=""),"",IF(M301=MAX(M301:O301),"Under",IF(N301=MAX(M301:O301),"Over","Normal")))

Sheet BIA_MNA_Staff
A1: record_id | B1: assessment_id | C1: assessment_date | D1: staff_id | E1: height_cm | F1: weight_kg | G1: bmi | H1: fat_mass_kg | I1: pbf | J1: vfat_level | K1: muscle_mass_kg | L1: bone_mass_kg | M1: tbw | N1: bmr_kcal | O1: mna_s1 | P1: mna_s2 | Q1: mna_s3 | R1: mna_s4 | S1: mna_s5 | T1: mna_s6 | U1: mna_screen_total | V1: mna_screen_cat | W1: mna_a1 | X1: mna_a2 | Y1: mna_a3 | Z1: mna_a4 | AA1: mna_a5 | AB1: mna_a6 | AC1: mna_a7 | AD1: mna_a8 | AE1: mna_a9 | AF1: mna_a10 | AG1: mna_a11 | AH1: mna_a12 | AI1: mna_ass_total | AJ1: mna_total | AK1: mna_total_cat | AL1: MAC | AM1: CC | AN1: bmi_class_glim | AO1: pbf_class | AP1: nutri_ref_class
A2: =IF(Participant_Data!A2="","",Participant_Data!A2) -> 1 | B2: =IF(Participant_Data!B2="","",Participant_Data!B2) | C2: =IF(Participant_Data!C2="","",Participant_Data!C2) | E2: 165 | F2: 75.05 | G2: =IF(OR(E2="",F2=""),"",F2/((E2/100)^2)) -> 27.566575 | H2: 19.14 | I2: 22.5 | J2: 16.5 | K2: 53.05 | L2: 2.9 | M2: 53.2 | N2: 1535 | O2: 2 | P2: 3 | Q2: 2 | R2: 2 | S2: 2 | T2: 3 | U2: 14 | V2: 1 | W2: 1 | X2: 0 | Y2: 1 | Z2: 2 | AA2: 1 | AB2: 1 | AC2: 1 | AD2: 2 | AE2: 2 | AF2: 1 | AG2: 1 | AH2: 1 | AI2: 14 | AJ2: 28 | AK2: 1 | AL2: 34 | AM2: 39 | AN2: =IF(OR(G2="",Participant_Data!E2=""),"",IF(Participant_Data!E2<70,IF(ROUND(G2,1)<18.5,"ขาด/เสี่ยงขาด",IF(ROUND(G2,1)>=25,"เสี่ยงเกิน/เกิน","ปกติ")),IF(ROUND(G2,1)<20,"ขาด/เสี่ยงขาด",IF(ROUND(G2,1)>=25,"เสี่ยงเกิน/เกิน","ปกติ")))) -> เสี่ยงเกิน/เกิน | AO2: =IF(OR(I2="",Participant_Data!G2=""),"",IF(Participant_Data!G2=1,IF(ROUND(I2,1)<15,"ขาด/เสี่ยงขาด",IF(ROUND(I2,1)>25,"เสี่ยงเกิน/เกิน","ปกติ")),IF(ROUND(I2,1)<20,"ขาด/เสี่ยงขาด",IF(ROUND(I2,1)>35,"เสี่ยงเกิน/เกิน","ปกติ")))) -> ปกติ | AP2: =IF(OR(AN2="",AO2=""),"",IF(OR(AN2="ขาด/เสี่ยงขาด",AO2="ขาด/เสี่ยงขาด"),"ขาด/เสี่ยงขาด",IF(OR(AN2="เสี่ยงเกิน/เกิน",AO2="เสี่ยงเกิน/เกิน"),"เสี่ยงเกิน/เกิน","ปกติ"))) -> เสี่ยงเกิน/เกิน
A3: =IF(Participant_Data!A3="","",Participant_Data!A3) -> 2 | B3: =IF(Participant_Data!B3="","",Participant_Data!B3) | C3: =IF(Participant_Data!C3="","",Participant_Data!C3) | E3: 146 | F3: 51.1 | G3: =IF(OR(E3="",F3=""),"",F3/((E3/100)^2)) -> 23.972603 | H3: 16.61 | I3: 32.5 | J3: 7.5 | K3: 32.65 | L3: 1.9 | M3: 51.7 | N3: 996 | O3: 2 | P3: 3 | Q3: 2 | R3: 2 | S3: 1 | T3: 3 | U3: 13 | V3: 1 | W3: 1 | X3: 1 | Y3: 1 | Z3: 2 | AA3: 0.5 | AB3: 1 | AC3: 1 | AD3: 2 | AE3: 1 | AF3: 1 | AG3: 1 | AH3: 1 | AI3: 13.5 | AJ3: 26.5 | AK3: 1 | AL3: 27.5 | AM3: 36.5 | AN3: =IF(OR(G3="",Participant_Data!E3=""),"",IF(Participant_Data!E3<70,IF(ROUND(G3,1)<18.5,"ขาด/เสี่ยงขาด",IF(ROUND(G3,1)>=25,"เสี่ยงเกิน/เกิน","ปกติ")),IF(ROUND(G3,1)<20,"ขาด/เสี่ยงขาด",IF(ROUND(G3,1)>=25,"เสี่ยงเกิน/เกิน","ปกติ")))) -> ปกติ | AO3: =IF(OR(I3="",Participant_Data!G3=""),"",IF(Participant_Data!G3=1,IF(ROUND(I3,1)<15,"ขาด/เสี่ยงขาด",IF(ROUND(I3,1)>25,"เสี่ยงเกิน/เกิน","ปกติ")),IF(ROUND(I3,1)<20,"ขาด/เสี่ยงขาด",IF(ROUND(I3,1)>35,"เสี่ยงเกิน/เกิน","ปกติ")))) -> ปกติ | AP3: =IF(OR(AN3="",AO3=""),"",IF(OR(AN3="ขาด/เสี่ยงขาด",AO3="ขาด/เสี่ยงขาด"),"ขาด/เสี่ยงขาด",IF(OR(AN3="เสี่ยงเกิน/เกิน",AO3="เสี่ยงเกิน/เกิน"),"เสี่ยงเกิน/เกิน","ปกติ"))) -> ปกติ
A4: =IF(Participant_Data!A4="","",Participant_Data!A4) -> 3 | B4: =IF(Participant_Data!B4="","",Participant_Data!B4) | C4: =IF(Participant_Data!C4="","",Participant_Data!C4) | E4: 153 | F4: 42.35 | G4: =IF(OR(E4="",F4=""),"",F4/((E4/100)^2)) -> 18.091332 | H4: 11.77 | I4: 27.8 | J4: 4 | K4: 29.05 | L4: 1.5 | M4: 48.1 | N4: 872 | O4: 2 | P4: 3 | Q4: 2 | R4: 2 | S4: 2 | T4: 0 | U4: 11 | V4: 2 | W4: 1 | X4: 1 | Y4: 1 | Z4: 1 | AA4: 0 | AB4: 0 | AC4: 1 | AD4: 2 | AE4: 1 | AF4: 2 | AG4: 1 | AH4: 0 | AI4: 11 | AJ4: 22 | AK4: 2 | AL4: 25 | AM4: 30.5 | AN4: =IF(OR(G4="",Participant_Data!E4=""),"",IF(Participant_Data!E4<70,IF(ROUND(G4,1)<18.5,"ขาด/เสี่ยงขาด",IF(ROUND(G4,1)>=25,"เสี่ยงเกิน/เกิน","ปกติ")),IF(ROUND(G4,1)<20,"ขาด/เสี่ยงขาด",IF(ROUND(G4,1)>=25,"เสี่ยงเกิน/เกิน","ปกติ")))) -> ขาด/เสี่ยงขาด | AO4: =IF(OR(I4="",Participant_Data!G4=""),"",IF(Participant_Data!G4=1,IF(ROUND(I4,1)<15,"ขาด/เสี่ยงขาด",IF(ROUND(I4,1)>25,"เสี่ยงเกิน/เกิน","ปกติ")),IF(ROUND(I4,1)<20,"ขาด/เสี่ยงขาด",IF(ROUND(I4,1)>35,"เสี่ยงเกิน/เกิน","ปกติ")))) -> ปกติ | AP4: =IF(OR(AN4="",AO4=""),"",IF(OR(AN4="ขาด/เสี่ยงขาด",AO4="ขาด/เสี่ยงขาด"),"ขาด/เสี่ยงขาด",IF(OR(AN4="เสี่ยงเกิน/เกิน",AO4="เสี่ยงเกิน/เกิน"),"เสี่ยงเกิน/เกิน","ปกติ"))) -> ขาด/เสี่ยงขาด
A5: =IF(Participant_Data!A5="","",Participant_Data!A5) -> 4 | B5: =IF(Participant_Data!B5="","",Participant_Data!B5) | C5: =IF(Participant_Data!C5="","",Participant_Data!C5) | E5: 143 | F5: 30.9 | G5: =IF(OR(E5="",F5=""),"",F5/((E5/100)^2)) -> 15.110763 | H5: 3.86 | I5: 12.5 | J5: 1 | K5: 25.8 | L5: 1.2 | M5: 61.3 | N5: 744 | O5: 2 | P5: 3 | Q5: 2 | R5: 2 | S5: 2 | T5: 0 | U5: 11 | V5: 2 | W5: 1 | X5: 1 | Y5: 1 | Z5: 2 | AA5: 0.5 | AB5: 1 | AC5: 1 | AD5: 2 | AE5: 0 | AF5: 1 | AG5: 0 | AH5: 0 | AI5: 10.5 | AJ5: 21.5 | AK5: 2 | AL5: 19 | AM5: 28 | AN5: =IF(OR(G5="",Participant_Data!E5=""),"",IF(Participant_Data!E5<70,IF(ROUND(G5,1)<18.5,"ขาด/เสี่ยงขาด",IF(ROUND(G5,1)>=25,"เสี่ยงเกิน/เกิน","ปกติ")),IF(ROUND(G5,1)<20,"ขาด/เสี่ยงขาด",IF(ROUND(G5,1)>=25,"เสี่ยงเกิน/เกิน","ปกติ")))) -> ขาด/เสี่ยงขาด | AO5: =IF(OR(I5="",Participant_Data!G5=""),"",IF(Participant_Data!G5=1,IF(ROUND(I5,1)<15,"ขาด/เสี่ยงขาด",IF(ROUND(I5,1)>25,"เสี่ยงเกิน/เกิน","ปกติ")),IF(ROUND(I5,1)<20,"ขาด/เสี่ยงขาด",IF(ROUND(I5,1)>35,"เสี่ยงเกิน/เกิน","ปกติ")))) -> ขาด/เสี่ยงขาด | AP5: =IF(OR(AN5="",AO5=""),"",IF(OR(AN5="ขาด/เสี่ยงขาด",AO5="ขาด/เสี่ยงขาด"),"ขาด/เสี่ยงขาด",IF(OR(AN5="เสี่ยงเกิน/เกิน",AO5="เสี่ยงเกิน/เกิน"),"เสี่ยงเกิน/เกิน","ปกติ"))) -> ขาด/เสี่ยงขาด
A6: =IF(Participant_Data!A6="","",Participant_Data!A6) -> 5 | B6: =IF(Participant_Data!B6="","",Participant_Data!B6) | C6: =IF(Participant_Data!C6="","",Participant_Data!C6) | E6: 160 | F6: 60.05 | G6: =IF(OR(E6="",F6=""),"",F6/((E6/100)^2)) -> 23.457031 | H6: 13.27 | I6: 22.1 | J6: 6.5 | K6: 43.85 | L6: 2.9 | M6: 55.4 | N6: 1317 | O6: 2 | P6: 3 | Q6: 2 | R6: 2 | S6: 1 | T6: 3 | U6: 13 | V6: 1 | W6: 1 | X6: 1 | Y6: 1 | Z6: 1 | AA6: 1 | AB6: 1 | AC6: 1 | AD6: 2 | AE6: 2 | AF6: 1 | AG6: 1 | AH6: 1 | AI6: 14 | AJ6: 27 | AK6: 1 | AL6: 28 | AM6: 34 | AN6: =IF(OR(G6="",Participant_Data!E6=""),"",IF(Participant_Data!E6<70,IF(ROUND(G6,1)<18.5,"ขาด/เสี่ยงขาด",IF(ROUND(G6,1)>=25,"เสี่ยงเกิน/เกิน","ปกติ")),IF(ROUND(G6,1)<20,"ขาด/เสี่ยงขาด",IF(ROUND(G6,1)>=25,"เสี่ยงเกิน/เกิน","ปกติ")))) -> ปกติ | AO6: =IF(OR(I6="",Participant_Data!G6=""),"",IF(Participant_Data!G6=1,IF(ROUND(I6,1)<15,"ขาด/เสี่ยงขาด",IF(ROUND(I6,1)>25,"เสี่ยงเกิน/เกิน","ปกติ")),IF(ROUND(I6,1)<20,"ขาด/เสี่ยงขาด",IF(ROUND(I6,1)>35,"เสี่ยงเกิน/เกิน","ปกติ")))) -> ปกติ | AP6: =IF(OR(AN6="",AO6=""),"",IF(OR(AN6="ขาด/เสี่ยงขาด",AO6="ขาด/เสี่ยงขาด"),"ขาด/เสี่ยงขาด",IF(OR(AN6="เสี่ยงเกิน/เกิน",AO6="เสี่ยงเกิน/เกิน"),"เสี่ยงเกิน/เกิน","ปกติ"))) -> ปกติ
A7: =IF(Participant_Data!A7="","",Participant_Data!A7) -> 6 | B7: =IF(Participant_Data!B7="","",Participant_Data!B7) | C7: =IF(Participant_Data!C7="","",Participant_Data!C7) | E7: 153 | F7: 53.1 | G7: =IF(OR(E7="",F7=""),"",F7/((E7/100)^2)) -> 22.683583 | H7: 15.56 | I7: 29.3 | J7: 6.5 | K7: 35.45 | L7: 2.1 | M7: 50.6 | N7: 1076 | O7: 2 | P7: 3 | Q7: 2 | R7: 2 | S7: 2 | T7: 2 | U7: 13 | V7: 1 | W7: 1 | X7: 1 | Y7: 1 | Z7: 1 | AA7: 0.5 | AB7: 1 | AC7: 1 | AD7: 2 | AE7: 2 | AF7: 1 | AG7: 1 | AH7: 1 | AI7: 13.5 | AJ7: 26.5 | AK7: 1 | AL7: 28 | AM7: 35 | AN7: =IF(OR(G7="",Participant_Data!E7=""),"",IF(Participant_Data!E7<70,IF(ROUND(G7,1)<18.5,"ขาด/เสี่ยงขาด",IF(ROUND(G7,1)>=25,"เสี่ยงเกิน/เกิน","ปกติ")),IF(ROUND(G7,1)<20,"ขาด/เสี่ยงขาด",IF(ROUND(G7,1)>=25,"เสี่ยงเกิน/เกิน","ปกติ")))) -> ปกติ | AO7: =IF(OR(I7="",Participant_Data!G7=""),"",IF(Participant_Data!G7=1,IF(ROUND(I7,1)<15,"ขาด/เสี่ยงขาด",IF(ROUND(I7,1)>25,"เสี่ยงเกิน/เกิน","ปกติ")),IF(ROUND(I7,1)<20,"ขาด/เสี่ยงขาด",IF(ROUND(I7,1)>35,"เสี่ยงเกิน/เกิน","ปกติ")))) -> ปกติ | AP7: =IF(OR(AN7="",AO7=""),"",IF(OR(AN7="ขาด/เสี่ยงขาด",AO7="ขาด/เสี่ยงขาด"),"ขาด/เสี่ยงขาด",IF(OR(AN7="เสี่ยงเกิน/เกิน",AO7="เสี่ยงเกิน/เกิน"),"เสี่ยงเกิน/เกิน","ปกติ"))) -> ปกติ
A8: =IF(Participant_Data!A8="","",Participant_Data!A8) -> 7 | B8: =IF(Participant_Data!B8="","",Participant_Data!B8) | C8: =IF(Participant_Data!C8="","",Participant_Data!C8) | E8: 163 | F8: 79.65 | G8: =IF(OR(E8="",F8=""),"",F8/((E8/100)^2)) -> 29.978546 | H8: 34.17 | I8: 42.9 | J8: 10.5 | K8: 42.65 | L8: 2.8 | M8: 44.5 | N8: 1397 | O8: 2 | P8: 3 | Q8: 2 | R8: 2 | S8: 2 | T8: 3 | U8: 14 | V8: 1 | W8: 1 | X8: 1 | Y8: 1 | Z8: 1 | AA8: 1 | AB8: 1 | AC8: 1 | AD8: 2 | AE8: 0 | AF8: 1 | AG8: 1 | AH8: 1 | AI8: 12 | AJ8: 26 | AK8: 1 | AL8: 36 | AM8: 41 | AN8: =IF(OR(G8="",Participant_Data!E8=""),"",IF(Participant_Data!E8<70,IF(ROUND(G8,1)<18.5,"ขาด/เสี่ยงขาด",IF(ROUND(G8,1)>=25,"เสี่ยงเกิน/เกิน","ปกติ")),IF(ROUND(G8,1)<20,"ขาด/เสี่ยงขาด",IF(ROUND(G8,1)>=25,"เสี่ยงเกิน/เกิน","ปกติ")))) -> เสี่ยงเกิน/เกิน | AO8: =IF(OR(I8="",Participant_Data!G8=""),"",IF(Participant_Data!G8=1,IF(ROUND(I8,1)<15,"ขาด/เสี่ยงขาด",IF(ROUND(I8,1)>25,"เสี่ยงเกิน/เกิน","ปกติ")),IF(ROUND(I8,1)<20,"ขาด/เสี่ยงขาด",IF(ROUND(I8,1)>35,"เสี่ยงเกิน/เกิน","ปกติ")))) -> เสี่ยงเกิน/เกิน | AP8: =IF(OR(AN8="",AO8=""),"",IF(OR(AN8="ขาด/เสี่ยงขาด",AO8="ขาด/เสี่ยงขาด"),"ขาด/เสี่ยงขาด",IF(OR(AN8="เสี่ยงเกิน/เกิน",AO8="เสี่ยงเกิน/เกิน"),"เสี่ยงเกิน/เกิน","ปกติ"))) -> เสี่ยงเกิน/เกิน
A9: =IF(Participant_Data!A9="","",Participant_Data!A9) -> 8 | B9: =IF(Participant_Data!B9="","",Participant_Data!B9) | C9: =IF(Participant_Data!C9="","",Participant_Data!C9) | E9: 156 | F9: 76.45 | G9: =IF(OR(E9="",F9=""),"",F9/((E9/100)^2)) -> 31.414366 | H9: 34.86 | I9: 45.6 | J9: 11.5 | K9: 39.1 | L9: 2.5 | M9: 42.7 | N9: 1283 | O9: 2 | P9: 3 | Q9: 2 | R9: 0 | S9: 2 | T9: 3 | U9: 12 | V9: 1 | W9: 1 | X9: 1 | Y9: 1 | Z9: 1 | AA9: 1 | AB9: 1 | AC9: 1 | AD9: 2 | AE9: 2 | AF9: 2 | AG9: 1 | AH9: 1 | AI9: 15 | AJ9: 27 | AK9: 1 | AL9: 36 | AM9: 41 | AN9: =IF(OR(G9="",Participant_Data!E9=""),"",IF(Participant_Data!E9<70,IF(ROUND(G9,1)<18.5,"ขาด/เสี่ยงขาด",IF(ROUND(G9,1)>=25,"เสี่ยงเกิน/เกิน","ปกติ")),IF(ROUND(G9,1)<20,"ขาด/เสี่ยงขาด",IF(ROUND(G9,1)>=25,"เสี่ยงเกิน/เกิน","ปกติ")))) -> เสี่ยงเกิน/เกิน | AO9: =IF(OR(I9="",Participant_Data!G9=""),"",IF(Participant_Data!G9=1,IF(ROUND(I9,1)<15,"ขาด/เสี่ยงขาด",IF(ROUND(I9,1)>25,"เสี่ยงเกิน/เกิน","ปกติ")),IF(ROUND(I9,1)<20,"ขาด/เสี่ยงขาด",IF(ROUND(I9,1)>35,"เสี่ยงเกิน/เกิน","ปกติ")))) -> เสี่ยงเกิน/เกิน | AP9: =IF(OR(AN9="",AO9=""),"",IF(OR(AN9="ขาด/เสี่ยงขาด",AO9="ขาด/เสี่ยงขาด"),"ขาด/เสี่ยงขาด",IF(OR(AN9="เสี่ยงเกิน/เกิน",AO9="เสี่ยงเกิน/เกิน"),"เสี่ยงเกิน/เกิน","ปกติ"))) -> เสี่ยงเกิน/เกิน
A10: =IF(Participant_Data!A10="","",Participant_Data!A10) -> 9 | B10: =IF(Participant_Data!B10="","",Participant_Data!B10) | C10: =IF(Participant_Data!C10="","",Participant_Data!C10) | E10: 150 | F10: 53 | G10: =IF(OR(E10="",F10=""),"",F10/((E10/100)^2)) -> 23.555556 | H10: 17.7 | I10: 33.4 | J10: 7.5 | K10: 33.4 | L10: 1.9 | M10: 49.1 | N10: 1024 | O10: 2 | P10: 3 | Q10: 2 | R10: 2 | S10: 2 | T10: 3 | U10: 14 | V10: 1 | W10: 1 | X10: 1 | Y10: 1 | Z10: 2 | AA10: 1 | AB10: 1 | AC10: 1 | AD10: 2 | AE10: 2 | AF10: 2 | AG10: 1 | AH10: 1 | AI10: 16 | AJ10: 30 | AK10: 1 | AL10: 28 | AM10: 35 | AN10: =IF(OR(G10="",Participant_Data!E10=""),"",IF(Participant_Data!E10<70,IF(ROUND(G10,1)<18.5,"ขาด/เสี่ยงขาด",IF(ROUND(G10,1)>=25,"เสี่ยงเกิน/เกิน","ปกติ")),IF(ROUND(G10,1)<20,"ขาด/เสี่ยงขาด",IF(ROUND(G10,1)>=25,"เสี่ยงเกิน/เกิน","ปกติ")))) -> ปกติ | AO10: =IF(OR(I10="",Participant_Data!G10=""),"",IF(Participant_Data!G10=1,IF(ROUND(I10,1)<15,"ขาด/เสี่ยงขาด",IF(ROUND(I10,1)>25,"เสี่ยงเกิน/เกิน","ปกติ")),IF(ROUND(I10,1)<20,"ขาด/เสี่ยงขาด",IF(ROUND(I10,1)>35,"เสี่ยงเกิน/เกิน","ปกติ")))) -> ปกติ | AP10: =IF(OR(AN10="",AO10=""),"",IF(OR(AN10="ขาด/เสี่ยงขาด",AO10="ขาด/เสี่ยงขาด"),"ขาด/เสี่ยงขาด",IF(OR(AN10="เสี่ยงเกิน/เกิน",AO10="เสี่ยงเกิน/เกิน"),"เสี่ยงเกิน/เกิน","ปกติ"))) -> ปกติ
A11: =IF(Participant_Data!A11="","",Participant_Data!A11) -> 10 | B11: =IF(Participant_Data!B11="","",Participant_Data!B11) | C11: =IF(Participant_Data!C11="","",Participant_Data!C11) | E11: 150 | F11: 59.2 | G11: =IF(OR(E11="",F11=""),"",F11/((E11/100)^2)) -> 26.311111 | H11: 22.08 | I11: 37.3 | J11: 8.5 | K11: 35 | L11: 2.1 | M11: 48.5 | N11: 1099 | O11: 2 | P11: 3 | Q11: 2 | R11: 2 | S11: 2 | T11: 3 | U11: 14 | V11: 1 | W11: 1 | X11: 1 | Y11: 1 | Z11: 2 | AA11: 0.5 | AB11: 1 | AC11: 1 | AD11: 2 | AE11: 1 | AF11: 0.5 | AG11: 1 | AH11: 1 | AI11: 13 | AJ11: 27 | AK11: 1 | AL11: 31 | AM11: 40 | AN11: =IF(OR(G11="",Participant_Data!E11=""),"",IF(Participant_Data!E11<70,IF(ROUND(G11,1)<18.5,"ขาด/เสี่ยงขาด",IF(ROUND(G11,1)>=25,"เสี่ยงเกิน/เกิน","ปกติ")),IF(ROUND(G11,1)<20,"ขาด/เสี่ยงขาด",IF(ROUND(G11,1)>=25,"เสี่ยงเกิน/เกิน","ปกติ")))) -> เสี่ยงเกิน/เกิน | AO11: =IF(OR(I11="",Participant_Data!G11=""),"",IF(Participant_Data!G11=1,IF(ROUND(I11,1)<15,"ขาด/เสี่ยงขาด",IF(ROUND(I11,1)>25,"เสี่ยงเกิน/เกิน","ปกติ")),IF(ROUND(I11,1)<20,"ขาด/เสี่ยงขาด",IF(ROUND(I11,1)>35,"เสี่ยงเกิน/เกิน","ปกติ")))) -> เสี่ยงเกิน/เกิน | AP11: =IF(OR(AN11="",AO11=""),"",IF(OR(AN11="ขาด/เสี่ยงขาด",AO11="ขาด/เสี่ยงขาด"),"ขาด/เสี่ยงขาด",IF(OR(AN11="เสี่ยงเกิน/เกิน",AO11="เสี่ยงเกิน/เกิน"),"เสี่ยงเกิน/เกิน","ปกติ"))) -> เสี่ยงเกิน/เกิน
A12: =IF(Participant_Data!A12="","",Participant_Data!A12) -> 11 | B12: =IF(Participant_Data!B12="","",Participant_Data!B12) | C12: =IF(Participant_Data!C12="","",Participant_Data!C12) | E12: 158 | F12: 50.65 | G12: =IF(OR(E12="",F12=""),"",F12/((E12/100)^2)) -> 20.289216 | H12: 16.01 | I12: 31.6 | J12: 6 | K12: 32.75 | L12: 1.9 | M12: 44.1 | N12: 996 | O12: 1 | P12: 3 | Q12: 2 | R12: 2 | S12: 1 | T12: 1 | U12: 10 | V12: 2 | W12: 1 | X12: 1 | Y12: 1 | Z12: 2 | AA12: 0.5 | AB12: 1 | AC12: 1 | AD12: 2 | AE12: 2 | AF12: 2 | AG12: 1 | AH12: 1 | AI12: 15.5 | AJ12: 25.5 | AK12: 1 | AL12: 26 | AM12: 33.5 | AN12: =IF(OR(G12="",Participant_Data!E12=""),"",IF(Participant_Data!E12<70,IF(ROUND(G12,1)<18.5,"ขาด/เสี่ยงขาด",IF(ROUND(G12,1)>=25,"เสี่ยงเกิน/เกิน","ปกติ")),IF(ROUND(G12,1)<20,"ขาด/เสี่ยงขาด",IF(ROUND(G12,1)>=25,"เสี่ยงเกิน/เกิน","ปกติ")))) -> ปกติ | AO12: =IF(OR(I12="",Participant_Data!G12=""),"",IF(Participant_Data!G12=1,IF(ROUND(I12,1)<15,"ขาด/เสี่ยงขาด",IF(ROUND(I12,1)>25,"เสี่ยงเกิน/เกิน","ปกติ")),IF(ROUND(I12,1)<20,"ขาด/เสี่ยงขาด",IF(ROUND(I12,1)>35,"เสี่ยงเกิน/เกิน","ปกติ")))) -> ปกติ | AP12: =IF(OR(AN12="",AO12=""),"",IF(OR(AN12="ขาด/เสี่ยงขาด",AO12="ขาด/เสี่ยงขาด"),"ขาด/เสี่ยงขาด",IF(OR(AN12="เสี่ยงเกิน/เกิน",AO12="เสี่ยงเกิน/เกิน"),"เสี่ยงเกิน/เกิน","ปกติ"))) -> ปกติ
A13: =IF(Participant_Data!A13="","",Participant_Data!A13) -> 12 | B13: =IF(Participant_Data!B13="","",Participant_Data!B13) | C13: =IF(Participant_Data!C13="","",Participant_Data!C13) | E13: 156 | F13: 56.2 | G13: =IF(OR(E13="",F13=""),"",F13/((E13/100)^2)) -> 23.09336 | H13: 17.82 | I13: 31.7 | J13: 6.5 | K13: 36.15 | L13: 2.2 | M13: 50.6 | N13: 1113 | O13: 2 | P13: 3 | Q13: 2 | R13: 0 | S13: 2 | T13: 3 | U13: 12 | V13: 1 | W13: 1 | X13: 1 | Y13: 1 | Z13: 1 | AA13: 1 | AB13: 1 | AC13: 1 | AD13: 2 | AE13: 2 | AF13: 2 | AG13: 1 | AH13: 1 | AI13: 15 | AJ13: 27 | AK13: 1 | AL13: 26 | AM13: 35 | AN13: =IF(OR(G13="",Participant_Data!E13=""),"",IF(Participant_Data!E13<70,IF(ROUND(G13,1)<18.5,"ขาด/เสี่ยงขาด",IF(ROUND(G13,1)>=25,"เสี่ยงเกิน/เกิน","ปกติ")),IF(ROUND(G13,1)<20,"ขาด/เสี่ยงขาด",IF(ROUND(G13,1)>=25,"เสี่ยงเกิน/เกิน","ปกติ")))) -> ปกติ | AO13: =IF(OR(I13="",Participant_Data!G13=""),"",IF(Participant_Data!G13=1,IF(ROUND(I13,1)<15,"ขาด/เสี่ยงขาด",IF(ROUND(I13,1)>25,"เสี่ยงเกิน/เกิน","ปกติ")),IF(ROUND(I13,1)<20,"ขาด/เสี่ยงขาด",IF(ROUND(I13,1)>35,"เสี่ยงเกิน/เกิน","ปกติ")))) -> ปกติ | AP13: =IF(OR(AN13="",AO13=""),"",IF(OR(AN13="ขาด/เสี่ยงขาด",AO13="ขาด/เสี่ยงขาด"),"ขาด/เสี่ยงขาด",IF(OR(AN13="เสี่ยงเกิน/เกิน",AO13="เสี่ยงเกิน/เกิน"),"เสี่ยงเกิน/เกิน","ปกติ"))) -> ปกติ
... A201: =IF(Participant_Data!A201="","",Participant_Data!A201) -> 200 | B201: =IF(Participant_Data!B201="","",Participant_Data!B201) | C201: =IF(Participant_Data!C201="","",Participant_Data!C201) | E201: 170 | F201: 64.75 | G201: =IF(OR(E201="",F201=""),"",F201/((E201/100)^2)) -> 22.404844 | H201: 15.35 | I201: 23.7 | J201: 14.5 | K201: 46.85 | L201: 2.6 | M201: 43.3 | N201: 1333 | O201: 2 | P201: 1 | Q201: 2 | R201: 0 | S201: 1 | T201: 2 | U201: 8 | V201: 2 | W201: 1 | X201: 1 | Y201: 1 | Z201: 2 | AA201: 0 | AB201: 0 | AC201: 1 | AD201: 2 | AE201: 1 | AF201: 1 | AG201: 1 | AH201: 0 | AI201: 11 | AJ201: 19 | AK201: 2 | AL201: 27.5 | AM201: 30 | AN201: =IF(OR(G201="",Participant_Data!E201=""),"",IF(Participant_Data!E201<70,IF(ROUND(G201,1)<18.5,"ขาด/เสี่ยงขาด",IF(ROUND(G201,1)>=25,"เสี่ยงเกิน/เกิน","ปกติ")),IF(ROUND(G201,1)<20,"ขาด/เสี่ยงขาด",IF(ROUND(G201,1)>=25,"เสี่ยงเกิน/เกิน","ปกติ")))) -> ปกติ | AO201: =IF(OR(I201="",Participant_Data!G201=""),"",IF(Participant_Data!G201=1,IF(ROUND(I201,1)<15,"ขาด/เสี่ยงขาด",IF(ROUND(I201,1)>25,"เสี่ยงเกิน/เกิน","ปกติ")),IF(ROUND(I201,1)<20,"ขาด/เสี่ยงขาด",IF(ROUND(I201,1)>35,"เสี่ยงเกิน/เกิน","ปกติ")))) -> ปกติ | AP201: =IF(OR(AN201="",AO201=""),"",IF(OR(AN201="ขาด/เสี่ยงขาด",AO201="ขาด/เสี่ยงขาด"),"ขาด/เสี่ยงขาด",IF(OR(AN201="เสี่ยงเกิน/เกิน",AO201="เสี่ยงเกิน/เกิน"),"เสี่ยงเกิน/เกิน","ปกติ"))) -> ปกติ
A202: =IF(Participant_Data!A202="","",Participant_Data!A202) -> 201 | B202: =IF(Participant_Data!B202="","",Participant_Data!B202) | C202: =IF(Participant_Data!C202="","",Participant_Data!C202) | G202: =IF(OR(E202="",F202=""),"",F202/((E202/100)^2)) | U202: =IF(COUNTA(O202:T202)=0,"",SUM(O202:T202)) | V202: =IF(U202="","",IF(U202>=12,"Normal",IF(U202>=8,"At risk","Malnourished"))) | AI202: =IF(COUNTA(W202:AH202)=0,"",SUM(W202:AH202)) | AJ202: =IF(OR(U202="",AI202=""),"",U202+AI202) | AK202: =IF(AJ202="","",IF(AJ202>=24,"Normal",IF(AJ202>=17,"At risk","Malnourished"))) | AN202: =IF(OR(G202="",Participant_Data!E202=""),"",IF(Participant_Data!E202<70,IF(ROUND(G202,1)<18.5,"ขาด/เสี่ยงขาด",IF(ROUND(G202,1)>=25,"เสี่ยงเกิน/เกิน","ปกติ")),IF(ROUND(G202,1)<20,"ขาด/เสี่ยงขาด",IF(ROUND(G202,1)>=25,"เสี่ยงเกิน/เกิน","ปกติ")))) | AO202: =IF(OR(I202="",Participant_Data!G202=""),"",IF(Participant_Data!G202=1,IF(ROUND(I202,1)<15,"ขาด/เสี่ยงขาด",IF(ROUND(I202,1)>25,"เสี่ยงเกิน/เกิน","ปกติ")),IF(ROUND(I202,1)<20,"ขาด/เสี่ยงขาด",IF(ROUND(I202,1)>35,"เสี่ยงเกิน/เกิน","ปกติ")))) | AP202: =IF(OR(AN202="",AO202=""),"",IF(OR(AN202="ขาด/เสี่ยงขาด",AO202="ขาด/เสี่ยงขาด"),"ขาด/เสี่ยงขาด",IF(OR(AN202="เสี่ยงเกิน/เกิน",AO202="เสี่ยงเกิน/เกิน"),"เสี่ยงเกิน/เกิน","ปกติ")))
A203: =IF(Participant_Data!A203="","",Participant_Data!A203) -> 202 | B203: =IF(Participant_Data!B203="","",Participant_Data!B203) | C203: =IF(Participant_Data!C203="","",Participant_Data!C203) | G203: =IF(OR(E203="",F203=""),"",F203/((E203/100)^2)) | U203: =IF(COUNTA(O203:T203)=0,"",SUM(O203:T203)) | V203: =IF(U203="","",IF(U203>=12,"Normal",IF(U203>=8,"At risk","Malnourished"))) | AI203: =IF(COUNTA(W203:AH203)=0,"",SUM(W203:AH203)) | AJ203: =IF(OR(U203="",AI203=""),"",U203+AI203) | AK203: =IF(AJ203="","",IF(AJ203>=24,"Normal",IF(AJ203>=17,"At risk","Malnourished"))) | AN203: =IF(OR(G203="",Participant_Data!E203=""),"",IF(Participant_Data!E203<70,IF(ROUND(G203,1)<18.5,"ขาด/เสี่ยงขาด",IF(ROUND(G203,1)>=25,"เสี่ยงเกิน/เกิน","ปกติ")),IF(ROUND(G203,1)<20,"ขาด/เสี่ยงขาด",IF(ROUND(G203,1)>=25,"เสี่ยงเกิน/เกิน","ปกติ")))) | AO203: =IF(OR(I203="",Participant_Data!G203=""),"",IF(Participant_Data!G203=1,IF(ROUND(I203,1)<15,"ขาด/เสี่ยงขาด",IF(ROUND(I203,1)>25,"เสี่ยงเกิน/เกิน","ปกติ")),IF(ROUND(I203,1)<20,"ขาด/เสี่ยงขาด",IF(ROUND(I203,1)>35,"เสี่ยงเกิน/เกิน","ปกติ")))) | AP203: =IF(OR(AN203="",AO203=""),"",IF(OR(AN203="ขาด/เสี่ยงขาด",AO203="ขาด/เสี่ยงขาด"),"ขาด/เสี่ยงขาด",IF(OR(AN203="เสี่ยงเกิน/เกิน",AO203="เสี่ยงเกิน/เกิน"),"เสี่ยงเกิน/เกิน","ปกติ")))
A204: =IF(Participant_Data!A204="","",Participant_Data!A204) -> 203 | B204: =IF(Participant_Data!B204="","",Participant_Data!B204) | C204: =IF(Participant_Data!C204="","",Participant_Data!C204) | G204: =IF(OR(E204="",F204=""),"",F204/((E204/100)^2)) | U204: =IF(COUNTA(O204:T204)=0,"",SUM(O204:T204)) | V204: =IF(U204="","",IF(U204>=12,"Normal",IF(U204>=8,"At risk","Malnourished"))) | AI204: =IF(COUNTA(W204:AH204)=0,"",SUM(W204:AH204)) | AJ204: =IF(OR(U204="",AI204=""),"",U204+AI204) | AK204: =IF(AJ204="","",IF(AJ204>=24,"Normal",IF(AJ204>=17,"At risk","Malnourished"))) | AN204: =IF(OR(G204="",Participant_Data!E204=""),"",IF(Participant_Data!E204<70,IF(ROUND(G204,1)<18.5,"ขาด/เสี่ยงขาด",IF(ROUND(G204,1)>=25,"เสี่ยงเกิน/เกิน","ปกติ")),IF(ROUND(G204,1)<20,"ขาด/เสี่ยงขาด",IF(ROUND(G204,1)>=25,"เสี่ยงเกิน/เกิน","ปกติ")))) | AO204: =IF(OR(I204="",Participant_Data!G204=""),"",IF(Participant_Data!G204=1,IF(ROUND(I204,1)<15,"ขาด/เสี่ยงขาด",IF(ROUND(I204,1)>25,"เสี่ยงเกิน/เกิน","ปกติ")),IF(ROUND(I204,1)<20,"ขาด/เสี่ยงขาด",IF(ROUND(I204,1)>35,"เสี่ยงเกิน/เกิน","ปกติ")))) | AP204: =IF(OR(AN204="",AO204=""),"",IF(OR(AN204="ขาด/เสี่ยงขาด",AO204="ขาด/เสี่ยงขาด"),"ขาด/เสี่ยงขาด",IF(OR(AN204="เสี่ยงเกิน/เกิน",AO204="เสี่ยงเกิน/เกิน"),"เสี่ยงเกิน/เกิน","ปกติ")))
A205: =IF(Participant_Data!A205="","",Participant_Data!A205) -> 204 | B205: =IF(Participant_Data!B205="","",Participant_Data!B205) | C205: =IF(Participant_Data!C205="","",Participant_Data!C205) | G205: =IF(OR(E205="",F205=""),"",F205/((E205/100)^2)) | U205: =IF(COUNTA(O205:T205)=0,"",SUM(O205:T205)) | V205: =IF(U205="","",IF(U205>=12,"Normal",IF(U205>=8,"At risk","Malnourished"))) | AI205: =IF(COUNTA(W205:AH205)=0,"",SUM(W205:AH205)) | AJ205: =IF(OR(U205="",AI205=""),"",U205+AI205) | AK205: =IF(AJ205="","",IF(AJ205>=24,"Normal",IF(AJ205>=17,"At risk","Malnourished"))) | AN205: =IF(OR(G205="",Participant_Data!E205=""),"",IF(Participant_Data!E205<70,IF(ROUND(G205,1)<18.5,"ขาด/เสี่ยงขาด",IF(ROUND(G205,1)>=25,"เสี่ยงเกิน/เกิน","ปกติ")),IF(ROUND(G205,1)<20,"ขาด/เสี่ยงขาด",IF(ROUND(G205,1)>=25,"เสี่ยงเกิน/เกิน","ปกติ")))) | AO205: =IF(OR(I205="",Participant_Data!G205=""),"",IF(Participant_Data!G205=1,IF(ROUND(I205,1)<15,"ขาด/เสี่ยงขาด",IF(ROUND(I205,1)>25,"เสี่ยงเกิน/เกิน","ปกติ")),IF(ROUND(I205,1)<20,"ขาด/เสี่ยงขาด",IF(ROUND(I205,1)>35,"เสี่ยงเกิน/เกิน","ปกติ")))) | AP205: =IF(OR(AN205="",AO205=""),"",IF(OR(AN205="ขาด/เสี่ยงขาด",AO205="ขาด/เสี่ยงขาด"),"ขาด/เสี่ยงขาด",IF(OR(AN205="เสี่ยงเกิน/เกิน",AO205="เสี่ยงเกิน/เกิน"),"เสี่ยงเกิน/เกิน","ปกติ")))
A206: =IF(Participant_Data!A206="","",Participant_Data!A206) -> 205 | B206: =IF(Participant_Data!B206="","",Participant_Data!B206) | C206: =IF(Participant_Data!C206="","",Participant_Data!C206) | G206: =IF(OR(E206="",F206=""),"",F206/((E206/100)^2)) | U206: =IF(COUNTA(O206:T206)=0,"",SUM(O206:T206)) | V206: =IF(U206="","",IF(U206>=12,"Normal",IF(U206>=8,"At risk","Malnourished"))) | AI206: =IF(COUNTA(W206:AH206)=0,"",SUM(W206:AH206)) | AJ206: =IF(OR(U206="",AI206=""),"",U206+AI206) | AK206: =IF(AJ206="","",IF(AJ206>=24,"Normal",IF(AJ206>=17,"At risk","Malnourished"))) | AN206: =IF(OR(G206="",Participant_Data!E206=""),"",IF(Participant_Data!E206<70,IF(ROUND(G206,1)<18.5,"ขาด/เสี่ยงขาด",IF(ROUND(G206,1)>=25,"เสี่ยงเกิน/เกิน","ปกติ")),IF(ROUND(G206,1)<20,"ขาด/เสี่ยงขาด",IF(ROUND(G206,1)>=25,"เสี่ยงเกิน/เกิน","ปกติ")))) | AO206: =IF(OR(I206="",Participant_Data!G206=""),"",IF(Participant_Data!G206=1,IF(ROUND(I206,1)<15,"ขาด/เสี่ยงขาด",IF(ROUND(I206,1)>25,"เสี่ยงเกิน/เกิน","ปกติ")),IF(ROUND(I206,1)<20,"ขาด/เสี่ยงขาด",IF(ROUND(I206,1)>35,"เสี่ยงเกิน/เกิน","ปกติ")))) | AP206: =IF(OR(AN206="",AO206=""),"",IF(OR(AN206="ขาด/เสี่ยงขาด",AO206="ขาด/เสี่ยงขาด"),"ขาด/เสี่ยงขาด",IF(OR(AN206="เสี่ยงเกิน/เกิน",AO206="เสี่ยงเกิน/เกิน"),"เสี่ยงเกิน/เกิน","ปกติ")))
